Workbook

Sheet survey
A1: GeoPoll Submission Form
A2: FAO - Household Questionnaire | P2: Additional notes
A3: Q # | B3: Q Name | C3: Suggested Qname | D3: English | E3: Length | F3: Arabic | G3: Length | H3: Q Type | I3: Randomize | J3: Conditional | K3: Programming Instructions | L3: Skip Pattern | M3: Codes | N3: Default skip patterns & conditional | O3: Specify skip pattern variable (from blue text) | Q3: Estimated percentage of repondents | T3: Mandatory | X3: Duration (sec) | Y3: Weighted duration | Z3: Core questions only
A4: A. PRESENTATION OF THE SURVEY AND ELIGIBILITY CRITERIA SELECTION | T4: no | Y4: =IF(X4="","",X4*V4) | Z4: =IF(T4="yes",Y4,"")
A5: NA | B5: Optin | D5: Optin | E5: =LEN(D5) | F5: Optin | G5: =LEN(F5) | H5: Open Ended | I5: NA | J5: NA | K5: Form Type - TextBox | L5: Any Response = phone_number | M5: NA | N5: NA | T5: no | X5: 0 | Y5: =IF(X5="","",X5*Q5)
A6: NA | B6: phone_number | C6: phone_number | D6: Input the phone number that you are contacting: | E6: =LEN(D6) | F6: أدخل رقم الهاتف الذي تتصل به: | G6: =LEN(F6) | H6: Open Ended | I6: NA | J6: NA | K6: Form Type - TextBox | L6: Any Response = calldispo | M6: NA | N6: NA | T6: yes | X6: 0 | Y6: =IF(X6="","",X6*Q6) | Z6: 0
A7: NA | B7: calldispo | C7: calldispo | D7: Phone number: #CATI_MOBILENUMBER# 1)Someone answers 2)Answering machine 3)No answer 4)Hang up or refusal 5)Call back 6)Under review 7)Disconnected | E7: =LEN(D7) | F7: رقم الهاتف: #CATI_MOBILENUMBER# 1) يجيب شخص ما 2) جهاز الرد الالي 3) لا جواب 4) إنهاء المكالمة أو الرفض 5) معاودة الاتصال 6) قيد المراجعة 7) قطع الاتصال | G7: =LEN(F7) | H7: Single Choice | I7: NA | J7: NA | K7: Form Type - Buttons | L7: 1 = resp_language 2 = AnsweringMachine 3 = NoAnswer 4 = Refusal 5 = WhenCallBack 6 = UnderReview 7 = Disconnected | M7: NA | N7: NA | T7: no | X7: 14.695308 | Y7: =IF(X7="","",X7*Q7)
A8: NA | B8: AnsweringMachine | C8: calldispo_answeringmachine | D8: Reached an answering machine. | E8: =LEN(D8) | F8: لقد تم توجيهك إلى جهاز الرد الالي | G8: =LEN(F8) | H8: NA | I8: NA | J8: NA | K8: NA | L8: End Poll AnsweringMachine | M8: NA | N8: NA | T8: no | X8: 0 | Y8: =IF(X8="","",X8*Q8)
A9: NA | B9: NoAnswer | C9: calldispo_noanswer | D9: Phone rang and no one answered. | E9: =LEN(D9) | F9: رن الهاتف ولم يرد أحد | G9: =LEN(F9) | H9: NA | I9: NA | J9: NA | K9: NA | L9: End Poll NoAnswer | M9: NA | N9: NA | T9: no | X9: 0 | Y9: =IF(X9="","",X9*Q9)
A10: NA | B10: UnderReview | C10: calldispo_underreview | D10: Case needs review by a supervisor. | E10: =LEN(D10) | F10: الحالة تحتاج إلى مراجعة من قبل مشرف | G10: =LEN(F10) | H10: NA | I10: NA | J10: NA | K10: NA | L10: End Poll UnderReview | M10: NA | N10: NA | T10: no | X10: 0 | Y10: =IF(X10="","",X10*Q10)
A11: NA | B11: Disconnected | C11: calldispo_disconnected | D11: Phone was disconnected or out of service. | E11: =LEN(D11) | F11: تم فصل الهاتف أو الهاتف خارج الخدمة | G11: =LEN(F11) | H11: NA | I11: NA | J11: NA | K11: NA | L11: End Poll Disconnected | M11: NA | N11: NA | T11: no | X11: 0 | Y11: =IF(X11="","",X11*Q11)
A12: NA | B12: resp_language | C12: resp_language | D12: Which language do you wish to proceed with? [OPERATOR: READ ANSWER CHOICES. SINGLE RESPONSE.] 1)Arabic | E12: =LEN(D12) | F12: ما هي اللغة التي ترغب في المتابعة بها؟ [المُشغل: اقرأ خيارات الإجابة. استجابة واحدة.] 1) عربي | G12: =LEN(F12) | H12: Single Choice | I12: NA | J12: NA | K12: Form Type - Buttons | L12: 1 = introduction [English] 2 = introduction [languages & add more if needed] | M12: NA | N12: For any response, go to introduction | P12: Arabic | T12: no | X12: 3.1032724 | Y12: =IF(X12="","",X12*Q12)
A13: NA | B13: introduction | C13: introduction | D13: Hello sir/ma'am, my name is #OPERATOR#, and I am calling from GeoPoll Polling Agency on behalf of the Food and Agriculture Organization of the United Nations [FAO]. We are conducting a survey on household livelihoods and the ability to access food in your area. I would like to ask you some questions about your household. The survey usually takes 20-30 minutes to complete. Any information that you provide will be kept strictly confidential, only used for the purpose of the survey and will not be shown to other people. Your voluntary participation in the outcome of this interview is NOT IN ANY WAY linked to your personal chance of receiving any assistance. This is voluntary and you can choose not to answer any or all of the questions if you want. However, we hope that you will participate since your views are important. Please note that this call may be recorded for quality purposes. Do you have any questions? [OPERATOR: ADDRESS QUESTIONS FROM RESPONDENT, IF ANY.] 1)CONTINUE | E13: =LEN(D13) | F13: مرحبًا سيدي / سيدتي ، اسمي #OPERATOR#. أتصل من وكالة GeoPoll الاستقصائية نيابة عن منظمة الأغذية والزراعة للأمم المتحدة (الفاو). نجري دراسة استقصائية حول سبل عيش الأسر والقدرة على الوصول إلى الغذاء في منطقتك. أود أن أطرح عليك بعض الأسئلة حول أسرتك. يستغرق الاستبيان عادةً 20-30 دقيقة. سيتم الاحتفاظ بسرية تامة بأي معلومات تقدمها ، ولن يتم استخدامها إلا لغرض الدراسة ولن يتم عرضها لأشخاص آخرين. إن مشاركتك الطوعية في نتيجة هذه الدراسة ليست مرتبطة بأي شكل من الأشكال بفرصتك الشخصية في تلقي أي مساعدة. هذا تطوعي ويمكنك اختيار عدم الإجابة على أي من الأسئلة أو جميعها إذا كنت تريد ذلك. ومع ذلك ، نأمل أن تشارك لأن آرائك مهمة. يرجى الملاحظة أنه قد يتم تسجيل هذه المكالمة لغاية مراقبة الجودة. هل لديك اسئلة؟ [المُشغل: أجب على أسئلة المُجيب ، إن وجدت.] 1) تابع | G13: =LEN(F13) | H13: Single Choice | I13: NA | J13: NA | K13: Form Type - Buttons | L13: 1 = Agree | M13: NA | N13: For any response, go to Agree | P13: 0 | T13: no | X13: 37.418449 | Y13: =IF(X13="","",X13*Q13)
A14: NA | B14: Agree | C14: resp_agree | D14: Are you interested in participating in this survey? [OPERATOR: SINGLE RESPONSE] 1)Yes 2)Not now but another time in the week 3)No | E14: =LEN(D14) | F14: هل لديك رغبة في بالمشاركة في هذه الدراسة؟ [المشغل: استجابة واحدة] 1) نعم 2) ليس الآن ولكن في وقت آخر في الأسبوع 3) لا | G14: =LEN(F14) | H14: StartRecording | I14: NA | J14: NA | K14: Form Type - Buttons | L14: 1 = [id_panel OR resp_firstname] 2 = WhenCallBack 3 = resp_refusalwhy | M14: NA | N14: if Agree = 1, go to id_panel OR resp_firstname if Agree = 2, go to WhenCallBack if Agree = 3, go to resp_refusalwhy | O14: id_panel | Q14: 1 | T14: no | X14: 3.8059516 | Y14: =IF(X14="","",X14*Q14)
A15: NA | B15: id_panel | C15: id_panel | D15: Have you or any member of your household received a call on behalf of FAO regarding this topic in the past two years? [OPERATOR: SINGLE RESPONSE.] 1)YES 2)NO 3)DON'T KNOW | E15: =LEN(D15) | F15: هل تلقيت انت أو أي أحد من أفراد أسرتك أي مكالمه بالنيابة عن منظمة الأغذيه و الزراعه [ الفاو ] بخصوص هذا الموضوع خلال العامين السابقين ؟ [ المشغل : أجابه واحده ] 1)نعم 2)لا 3)لا أعرف | G15: =LEN(F15) | H15: Single Choice | I15: NA | J15: NA | K15: Form Type - Buttons | L15: 1-3 = resp_firstname | M15: NA | N15: For any response, go to resp_firstname | P15: It is highly recommended to include the question id_panel if a panelist approach is used. | Q15: 1 | T15: no
A16: NA | B16: resp_refusalwhy | C16: resp_refusalwhy | D16: Please let us know why you have REFUSED to take the survey. [OPERATOR: SINGLE RESPONSE] 1)Not interested 2)Do not want to be recorded 3)Other [specify] | E16: =LEN(D16) | F16: يرجى إخبارنا سبب رفضك للمشاركة في هذه الدراسة. [المشغل: استجابة واحدة] 1) غير مهتم 2) لا أريد أن يتم تسجيلي 3) آخر [حدد] | G16: =LEN(F16) | H16: Open Ended - Single Choice | I16: NA | J16: NA | K16: Form Type - RadioList | L16: Any Response = Refusal | M16: NA | N16: For any response, go to Refusal | Q16: 1 | T16: no | X16: 0 | Y16: =IF(X16="","",X16*Q16)
A17: NA | B17: WhenCallBack | C17: resp_whencallback | D17: When would it be a good time to call you back? [RECORD HH/MM/DD/MM OF CALLBACK] | E17: =LEN(D17) | F17: ما هو التاريخ / الوقت المناسب لمعاودة الاتصال بك؟ [RECORD HH / MM / DD / MM of CALLBACK] | G17: =LEN(F17) | H17: Open Ended | I17: NA | J17: NA | K17: Form Type - TextBox IsCallBackDemographic | L17: Any Response = CallbackMessageEN | M17: NA | N17: For any response, go to CallbackMessageEN | Q17: 1 | T17: no | X17: 0 | Y17: =IF(X17="","",X17*Q17)
A18: NA | B18: CallbackMessageEN | C18: callbackmessage_en | D18: Thank you, we will call you back at {WhenCallBack} you requested. Thank you again and have a great day! [OPERATOR: ENTER CALL NOTES BELOW, WHO YOU SPOKE TO AND WHAT THEY SAID] | E18: =LEN(D18) | F18: شكرًا لك ، سوف نعاود الاتصال بك في #WhenCallBack# الذي طلبته. شكرا لك مرة أخرى و نتمنى لك يوم جميل! [المُشغل: أدخل ملاحظات الاتصال أدناه ، مع من تحدثت وماذا قالوا] | G18: =LEN(F18) | H18: Open Ended | I18: NA | J18: NA | K18: Form Type - TextBox | L18: Any Response = End poll callback | M18: NA | N18: NA | Q18: 1 | T18: no | X18: 0 | Y18: =IF(X18="","",X18*Q18)
A19: NA | B19: Ineligible | C19: NA | D19: You are ineligible for this survey. Thank you for your time and please look out for future surveys! | E19: =LEN(D19) | F19: أنت غير مؤهل للمشاركة في هذه الدراسة، شكرًا لك على وقتك. ترقب دراسات GeoPoll المستقبلية! | G19: =LEN(F19) | H19: NA | I19: NA | J19: NA | K19: NA | L19: End Poll Ineligible | M19: NA | N19: NA | Q19: 1 | T19: no | X19: 0 | Y19: =IF(X19="","",X19*Q19)
A20: NA | B20: Refusal | C20: NA | D20: Thank you for your time, you will be removed from today's survey. | E20: =LEN(D20) | F20: شكراً جزيلاً على وقتك، سنقوم بحذف إسمك من دراسة اليوم. | G20: =LEN(F20) | H20: NA | I20: NA | J20: NA | K20: NA | L20: End poll declined | M20: NA | N20: NA | Q20: 1 | T20: no | X20: 0 | Y20: =IF(X20="","",X20*Q20)
A21: B. GENERAL INFORMATION & ELIGIBILITY CRITERIA | Y21: =IF(X21="","",X21*Q21) | Z21: =IF(T21="yes",Y21,"")
A22: NA | B22: resp_firstname | C22: resp_firstname | D22: What is your first name? [OPERATOR: RECORD THE RESPONDENT'S FIRST NAME. ENTER 999 FOR REFUSED.] | E22: =LEN(D22) | F22: ما اسمك؟ [المُشغل: سجل اسم المجيب. أدخل 999 في حالة الرفض.] | G22: =LEN(F22) | H22: Open Ended | I22: NA | J22: NA | K22: Form Type - TextBox | L22: Any Response = resp_lastname | M22: NA | N22: For any response, go to resp_lastname | Q22: =1 | T22: yes | X22: 25.874027 | Y22: =IF(X22="","",X22*Q22) | Z22: 25.87402725219727
A23: NA | B23: resp_lastname | C23: resp_lastname | D23: What is your last name? [OPERATOR: RECORD THE RESPONDENT'S LAST NAME. ENTER 999 FOR REFUSED.] | E23: =LEN(D23) | F23: ما هو اسم عائلتك؟ [المُشغل: سجل اسم عائلة المجيب. أدخل 999 في حالة الرفض.] | G23: =LEN(F23) | H23: Open Ended | I23: NA | J23: NA | K23: Form Type - TextBox | L23: Any Response = resp_age | M23: NA | N23: For any response, go to resp_age | Q23: =1 | T23: yes | X23: 8.5994816 | Y23: =IF(X23="","",X23*Q23) | Z23: 8.599481582641602
A24: 1 | B24: resp_age | C24: resp_age | D24: How old are you? [OPERATOR: RECORD AGE IN NUMBER OF YEARS. ROUND UP TO NEAREST WHOLE NUMBER. IF THE RESPONDENT GIVES BIRTH YEAR, REPEAT THE QUESTION. ENTER 00 FOR DON'T KNOW.] | E24: =LEN(D24) | F24: كم عمرك؟ [المُشغل: سجل العمر في عدد السنوات. قم بالتقريب لأقرب رقم كامل. إذا أعطى المجيب سنة الميلاد ، فكرر السؤال. أدخل 00 للا أعرف.] | G24: =LEN(F24) | H24: Range | I24: NA | J24: NA | K24: Form Type - TextBox | L24: 0-17 = Ineligible 18-100 = resp_gender 00 = Ineligible | M24: NA | N24: Only respondents from 18-100 will be eligible for the survey. | Q24: =1 | T24: yes | X24: 9.8907185 | Y24: =IF(X24="","",X24*Q24) | Z24: 9.890718460083008
A25: =A24+1 | B25: resp_gender | C25: resp_gender | D25: What is the gender of the respondent? [OPERATOR: DO NOT ASK THIS QUESTION OUT LOUD. LISTEN TO THE VOICE AND SELECT THE GENDER.] 1)Male 2)Female 3)DON'T KNOW 4)REFUSED | E25: =LEN(D25) | F25: ما هو جنس المجيب؟ [المُشغل: لا تطرح هذا السؤال. استمع إلى الصوت وحدد المربع الصحيح.] 1) ذكر 2) أنثى 3) لا أعرف 4) رفض الإجابة | G25: =LEN(F25) | H25: Single Choice | I25: NA | J25: NA | K25: Form Type - Buttons | L25: 1-4 = phone_number_conf | M25: NA | N25: For any response, go to phone_number_conf | Q25: =1 | T25: yes | X25: 1.7156482 | Y25: =IF(X25="","",X25*Q25) | Z25: 1.715648174285889
Q26: =1 | Y26: =IF(X26="","",X26*Q26) | Z26: =IF(T26="yes",Y26,"")
B27: phone_number_conf | C27: phone_number_conf | D27: Is the phone number I am calling you on yours or a household members? [OPERATOR: SINGLE RESPONSE.] 1)YES 2)NO 3)DON'T KNOW 4)REFUSED | E27: =LEN(D27) | F27: هل رقم الهاتف الذي أتصل به هو رقمك أو رقم أحد أفراد أسرتك؟ [المشغل: استجابة واحدة.] 1) نعم 2) لا 3) لا أعرف 4) رفض الإجابة | G27: =LEN(F27) | H27: Single Choice | I27: NA | J27: NA | K27: Form Type - Buttons | L27: 1 = contact_2 2 = phone_number_personal 3-4 = contact_2 | M27: NA | N27: if phone_number_conf = 1, go to contact_2 if phone_number_conf = 2, go to phone_number_personal if phone_number_conf = 3-4, go to contact_2 | Q27: =1 | T27: yes - panel | X27: 6.375237 | Y27: =IF(X27="","",X27*Q27)
B28: phone_number_personal | C28: phone_number_pers | D28: What is your phone number? [OPERATOR: RECORD THE NUMBER GIVEN] | E28: =LEN(D28) | F28: ما هو رقم هاتفك؟ ( المشغل: قم بتسجيل الرقم المعطى لك ) | G28: =LEN(F28) | H28: Open Ended | I28: NA | J28: NA | K28: Form Type - TextBox | L28: Any Response = contact_2 | M28: NA | N28: For any response, go to contact_2 | Q28: =1 | T28: yes - panel | X28: 28.700001 | Y28: =IF(X28="","",X28*Q28)
B29: contact_2 | C29: contact_2 | D29: Can you give me an additional phone number belonging to you, another household member or a close relation living outside of the household at which you can be reached? [OPERATOR: SINGLE RESPONSE.] 1)YES - mine 2)YES - other household member 3)YES - friend or relative [non-household member] 4)NO 5)DON'T KNOW 6)REFUSED | E29: =LEN(D29) | F29: هل يمكن أن تعطيني رقم هاتف إضافي يخصك، أو أحد أفراد الأسرة، أو قريب يعيش خارج المنزل ويمكن التواصل معك عبره؟ [المشغل: استجابة واحدة.] 1) نعم - لي 2) نعم - فرد اخر من أفراد الأسرة 3) نعم - صديق أو أحد الأقارب [ ليس فردا من أفراد الأسرة ] 4) لا 5) لا أعرف 6) رفض الإجابة | G29: =LEN(F29) | H29: Single Choice | I29: NA | J29: NA | K29: Form Type - Buttons | L29: 1-3 = phone_number_2 4-6 = hh_admin1 | M29: NA | N29: if contact_2 = 1-3, go to phone_number_2 if contact_2 = 4-6, go to contact_3 | Q29: =1 | T29: yes - panel | X29: 10.141817 | Y29: =IF(X29="","",X29*Q29)
B30: phone_number_2 | C30: phone_number_2 | D30: What is the additional phone number? [OPERATOR: RECORD THE NUMBER GIVEN] | E30: =LEN(D30) | F30: ما هو رقم الهاتف الإضافي؟ ( المشغل: قم بتسجيل الرقم المعطى لك ) | G30: =LEN(F30) | H30: Open Ended | I30: NA | J30: NA | K30: Form Type - TextBox | L30: Any Response = contact_2_name | M30: NA | N30: For any response, go to contact_2_name | Q30: =1 | T30: yes - panel | X30: 21.659983 | Y30: =IF(X30="","",X30*Q30)
B31: contact_2_name | C31: contact_2_name | D31: What is the name of the contact? [OPERATOR: RECORD THE NAME OF THE CONTACT FOR THE PHONE NUMBER.] | E31: =LEN(D31) | F31: ما هو اسم صاحب رقم الهاتف الإضافي الذي قمت بمشاركته؟ ( المشغل: قم بتسجيل اسم صاحب رقم الهاتف ) | G31: =LEN(F31) | H31: Open Ended | I31: NA | J31: Send if "contact_2" "Equals" "YES - other household member" Or "contact_2" "Equals" "YES - friend or relative [non-household member]" if not satisfied go to "contact_3" | K31: Form Type - TextBox | L31: Any Response = contact_3 | M31: NA | N31: Asked if response to contact_2 was "YES - other household member" or "YES - friend or relative [non-household member]". Otherwise, it skips to "contact_3". For any response, go to contact_3 | Q31: =1 | T31: yes - panel | X31: 11.821796 | Y31: =IF(X31="","",X31*Q31)
B32: contact_3 | C32: contact_3 | D32: Can you give me an additional phone number belonging to you, another household member or a close relation living outside of the household at which you can be reached? [OPERATOR: SINGLE RESPONSE.] 1)YES - mine 2)YES - other household member 3)YES - friend or relative [non-household member] 4)NO 5)DON'T KNOW 6)REFUSED | E32: =LEN(D32) | F32: هل يمكن أن تعطيني رقم هاتف إضافي يخصك، أو أحد أفراد الأسرة، أو قريب يعيش خارج المنزل ويمكن التواصل معك عبره؟ [المشغل: استجابة واحدة.] 1) نعم - لي 2) نعم - فرد اخر من أفراد الأسرة 3) نعم - صديق أو أحد الأقارب [ ليس فردا من أفراد الأسرة ] 4) لا 5) لا أعرف 6) رفض الإجابة | G32: =LEN(F32) | H32: Single Choice | I32: NA | J32: NA | K32: Form Type - Buttons | L32: 1-3= phone_number_3 4-6 = hh_admin1 | M32: NA | N32: if contact_3 = 1-3, go to phone_number_3 if contact_3 = 4-6, go to hh_admin1 | Q32: =1 | T32: yes - panel | X32: 3.163594 | Y32: =IF(X32="","",X32*Q32)
B33: phone_number_3 | C33: phone_number_3 | D33: What is the additional phone number? [OPERATOR: RECORD THE NUMBER GIVEN] | E33: =LEN(D33) | F33: ما هو رقم الهاتف الإضافي؟ ( المشغل: قم بتسجيل الرقم المعطى لك ) | G33: =LEN(F33) | H33: Open Ended | I33: NA | J33: NA | K33: Form Type - TextBox | L33: Any Response = contact_3_name | M33: NA | N33: For any response, go to contact_3_name | Q33: =1 | T33: yes - panel | X33: 10.830144 | Y33: =IF(X33="","",X33*Q33)
B34: contact_3_name | C34: phone_number_3_name | D34: What is the name of the contact? [OPERATOR: RECORD THE NAME OF THE CONTACT FOR THE PHONE NUMBER.] | E34: =LEN(D34) | F34: ما هو اسم صاحب رقم الهاتف الإضافي الذي قمت بمشاركته؟ (المشغل: قم بتسجيل اسم صاحب رقم الهاتف) | G34: =LEN(F34) | H34: Open Ended | I34: NA | J34: Send if "contact_3" "Equals" "YES - other household member" Or "contact_3" "Equals" "YES - friend or relative [non-household member]" if not satisfied go to "hh_admin1" | K34: Form Type - TextBox | L34: Any Response = hh_admin1 | M34: NA | N34: Asked if response to contact_3 was "YES - other household member" or "YES - friend or relative [non-household member]". Otherwise, it skips to "hh_admin1". For any response, go to hh_admin1 | Q34: =1 | T34: yes - panel | X34: 11.260417 | Y34: =IF(X34="","",X34*Q34)
Q35: =1 | Y35: =IF(X35="","",X35*Q35) | Z35: =IF(T35="yes",Y35,"")
A36: 3 | B36: hh_admin1 | C36: hh_admin1 | D36: Currently, in which Governorate does your household reside? [OPERATOR: SINGLE SELECTION.] [HINT: HOUSEHOLD CONSISTS OF ALL MEMBERS LIVING TOGETHER, SHARING RESOURCES & EATING FROM THE SAME POT.] 1)ADMIN1 2)DON'T KNOW 3)REFUSED | E36: =LEN(D36) | F36: حاليًا ، في أي محافظة تقيم أسرتك؟ [المشغل: استجابة واحدة.] [ملحوظة: تتكون الأسرة من جميع الأعضاء الذين يعيشون معًا ، ويتشاركون الموارد ويأكلون من نفس القدر.] 1) ADMIN 1 2) لا أعرف 3) رفض الإجابة | G36: =LEN(F36) | H36: Single Choice | I36: NA | J36: NA | K36: Form Type - Buttons IsDemographic - ADM1 | L36: 1 = hh_admin2_1 2-3 = Ineligible | M36: NA | N36: The administrative information will be updated by GeoPoll based on the sample design document and the administrative boundaries provided by the dashboard team after the questionnaire validation. | Q36: =1 | T36: yes | X36: 13.957259 | Y36: =IF(X36="","",X36*Q36) | Z36: 13.95725891910985
A37: =A36+1 | B37: hh_admin2_1 | C37: hh_admin2_1 | D37: Currently, in which District does your household reside? [OPERATOR: SINGLE RESPONSE.] 1)ADMIN2 2)DON'T KNOW 3)REFUSED | E37: =LEN(D37) | F37: حاليًا ، في أي مديرية تقيم أسرتك؟ [المشغل: استجابة واحدة.] 1) ADMIN 2 2) لا أعرف 3) رفض الإجابة | G37: =LEN(F37) | H37: Single Choice | I37: NA | J37: NA | K37: Form Type - Buttons IsDemographic - ADM2 | L37: 1 = hh_agricactivity 2-3 = Ineligible | M37: NA | Q37: =1 | T37: yes | X37: 7.954999 | Y37: =IF(X37="","",X37*Q37) | Z37: 7.954998970031738
B38: quotareached | C38: quotareached | D38: [OPERATOR: DO NOT READ. ANSWER QUESTION BELOW.] THIS RESPONDENT REPORTED THEY LIVE IN: {ADM1} {ADM2} 1)THE GOAL FOR THIS LOCATION HAS BEEN ACHIEVED - END SURVEY 2)THE GOAL FOR THIS LOCATION IS OPEN - CONTINUE SURVEY | E38: =LEN(D38) | F38: [المُشغل: لا تقرأ. أجب على السؤال أدناه.] أبلغ هذا المجيب أنه يعيش في: {ADM1} {ADM2} 1) تم تحقيق الهدف لهذا الموقع - إنه الاستبيان 2) لا يزال يتعين تحقيق الهدف لهذا الموقع - تابع الاستبيان | G38: =LEN(F38) | H38: Single Choice | I38: NA | J38: NA | K38: Form Type - Buttons | L38: 1 = End Poll Quota Reached 2 = hh_agricactivity | M38: NA
A39: =#REF!+1 | B39: hh_agricactivity | C39: hh_agricactivity | D39: Has anybody in your household produced crops or livestock for household consumption or for sale in the past 12 months, including household members currently away for transhumance? [OPERATOR: SINGLE RESPONSE. THIS IS THE MAIN SCREENING QUESTION.] [HINT FOR PROBING: Do you cultivate any plants to sale or consume? Do you raise any animals with the intent of selling or consuming them or their products like meat, milk, wool or leather? Is one of your household member currently away with cattle or other animals for transhumance?] 1)Yes - crop production 2)Yes - livestock production 3)Yes - both crop and livestock production 4)No 5)DON'T KNOW 6)REFUSED | E39: =LEN(D39) | F39: هل قام أي شخص في أسرتك بإنتاج المحاصيل أو الماشية للاستهلاك المنزلي أو للبيع خلال الاثني عشر شهرًا الماضية ، بما في ذلك أفراد الأسرة الغير موجودين بغرض التنقل الرعوي؟ [المشغل: استجابة واحدة. هذا هو سؤال الفرز الرئيسي.] [ملحوظة للتحقيق: هل قمت بزراعة أي نباتات للبيع أو الاستهلاك ؟ هل قمت بتربية أي حيوانات بنية البيع أو الاستهلاك أو انتاج منتجات مثل اللحوم و الالبان و الصوف و الجلد ؟ هل أي فرد من أفراد أسرتك حاليا بعيدًا عن الأسرة مع الماشية أو حيوانات أخري بغرض التنقل الرعوي ؟] 1) نعم - إنتاج المحاصيل 2) نعم - إنتاج الماشية 3) نعم - كل من إنتاج المحاصيل والماشية 4) لا 5) لا أعرف 6) رفض الإجابة | G39: =LEN(F39) | H39: Single Choice | I39: NA | J39: NA | K39: Form Type - Buttons | L39: 1-4 = resp_id or hh_fish 5-6 = Ineligible | M39: NA | N39: if hh_agricactivity = 1-4, go to resp_id or hh_fish. Otherwise, the respondent is ineligible. | O39: o_fishery_activity | Q39: =1 | T39: yes | X39: 24.410839 | Y39: =IF(X39="","",X39*Q39) | Z39: 24.41083908081055
B40: o_fishery_activity | D40: Has anybody in your household been involved in fishery and aquaculture for household consumption or sale in the past 12 months? [OPERATOR: SINGLE CHOICE.] 1)YES 2)NO 3) DON'T KNOW 4)REFUSED | F40: هل شارك أي فرد من افراد الأسرة في مصائد الأسماك وتربية الأحياء المائية لغرض الاستهلاك المنزلي أو للبيع خلال الاثني عشر شهرًا الماضية؟ [المُشغل: استجابة واحدة.] 1) نعم 2) لا 3) لا أعرف 4) رفض الإجابة | H40: Single Choice | L40: 1-4 = resp_id | N40: For any response, go to resp_id | O40: resp_id
...

Sheet Crop list
C3: Select top 10 crops | D3: GeoPoll code | E3: Dataset code | F3: Label (EN) | G3: Label (AR)
D4: {=_xlfn.SEQUENCE(90,1,1,1)} | E4: 1.1 | F4: Rice | G4: الرز
C5: x | D5: 2 | E5: 1.2 | F5: Wheat | G5: القمح
C6: x | D6: 3 | E6: 1.3 | F6: Millet | G6: الدخن
C7: x | D7: 4 | E7: 1.4 | F7: Sorghum | G7: الذرة الرفيعة
D8: 5 | E8: 1.5 | F8: Maize | G8: الذرة
D9: 6 | E9: 1.6 | F9: Barley | G9: الشعير
D10: 7 | E10: 1.99 | F10: Other Cereal | G10: الحبوب الأخرى
D11: 8 | E11: 2.1 | F11: Cassava | G11: الكسافا
C12: x | D12: 9 | E12: 2.2 | F12: Potatoe | G12: البطاطا
D13: 10 | E13: 2.3 | F13: Sweet Potatoes | G13: البطاطا الحلوة
D14: 11 | E14: 2.4 | F14: Yams | G14: اليام
D15: 12 | E15: 2.5 | F15: Carrots | G15: الجزر
D16: 13 | E16: 2.6 | F16: Cocoyam | G16: القلقاس
D17: 14 | E17: 2.99 | F17: Other tubers | G17: الدرنات الأخرى
D18: 15 | E18: 3.1 | F18: Beans | G18: الفاصوليا
C19: x | D19: 16 | E19: 3.2 | F19: Lentils | G19: العدس
D20: 17 | E20: 3.3 | F20: Peas | G20: البازيلاء
D21: 18 | E21: 3.4 | F21: Soybeans | G21: فول الصويا
D22: 19 | E22: 3.5 | F22: Chickpeas | G22: الحمص
D23: 20 | E23: 3.6 | F23: Fava beans | G23: الفول
D24: 21 | E24: 3.7 | F24: Broad beans | G24: الفاصوليا العريضة
D25: 22 | E25: 3.99 | F25: Other pulses | G25: البقول الاخرى
D26: 23 | E26: 4.1 | F26: Cabbage | G26: الملفوف
D27: 24 | E27: 4.2 | F27: Lettuce | G27: الخس
D28: 25 | E28: 4.3 | F28: Spinach-Amaranth | G28: السبانخ - القطيفة
D29: 26 | E29: 4.4 | F29: Cassava leaves | G29: أوراق الكسافا
D30: 27 | E30: 4.5 | F30: Potatoe leaves | G30: أوراق البطاطا
D31: 28 | E31: 4.6 | F31: Moringa | G31: المورينجا
... D35: 32 | E35: 4.99 | F35: Other leafy vegetables | G35: الخضار الورقية الأخرى
C36: x | D36: 33 | E36: 5.1 | F36: Tomatoes | G36: الطماطم
D37: 34 | E37: 5.2 | F37: Cucumber | G37: الخيار
D38: 35 | E38: 5.3 | F38: Pumpkin | G38: اليقطين
D39: 36 | E39: 5.4 | F39: Eggplant/aubergine | G39: الباذنجان
D40: 37 | E40: 5.5 | F40: Zucchini | G40: الكوسة
C41: x | D41: 38 | E41: 5.6 | F41: Okra | G41: البامية
D42: 39 | E42: 5.7 | F42: Bell pepper | G42: الفلفل حلو
D43: 40 | E43: 5.8 | F43: Onions | G43: بصل
D44: 41 | E44: 5.9 | F44: Haricot | G44: اللوبياء
D45: 42 | E45: 5.101 | F45: Green peas | G45: البازلاء الخضراء
...

Sheet Additional information
C2: Original | D2: Replacement (EN) | E2: Replacement (AR) | F2: Comment (EN) | G2: Comment (AR) | H2: Example (EN) | I2: Example (AR)
B3: FOR CORE QUESTIONS . (Mandatory to fill out) . | C3: ADMIN1 | D3: Governorate | E3: محافظة | F3: The first subdivision of the country, after national level; region; province; governorate; etc. | G3: التقسيم الأول للبلاد ، بعد المستوى الوطني ؛ منطقة؛ محافظة؛ ولاية ؛ إلخ. | H3: region | I3: منطقة
C4: ADMIN2 | D4: District | E4: مديرية | F4: The second subdivision of the country; district; municipality; LGA; etc. | G4: التقسيم الثاني للبلاد ؛ قضاء؛ بلدية؛ إلخ. | H4: district | I4: قضاء
C5: reference year | D5: last year | E5: العام الماضي | F5: Comparison questions will need need a reference year. Select whether you want to use "last year" or "a normal year" as a baseline. A "normal year" should refers to an average year from the past 5 years - make sure to train the enumerators accordingly. | G5: سوف تحتاج أسئلة المقارنة إلى سنة مرجعية. حدد ما إذا كنت تريد استخدام "العام الماضي" أو "العام العادي" كخط أساس. يجب أن يشير "العام العادي" إلى متوسط ​​عام من السنوات الخمس الماضية - تأكد من تدريب جامعي البيانات وفقًا لذلك. | H5: a normal year | I5: العام العادي
C6: season | D6: Ongoing season | E6: الموسم الحالي | F6: Name the crop season(s) of interest if there are several cropping seasons in the country (e.g. Meher and Belg in Ethiopia, rainy season / flood-recession cropping / irrigated dry season in the Sahel). You can refer to the “last season” or “ongoing season". | G6: قم بتسمية موسم (مواسم) المحاصيل ذات الأهمية إذا كان هناك عدة مواسم محصولية في البلد (على سبيل المثال ، Meher و Belg في إثيوبيا ، موسم الأمطار / محاصيل الركود بسبب الفيضانات / موسم الجفاف المروي في منطقة الساحل). يمكنك الرجوع إلى "الموسم الماضي" أو "الموسم الجاري". | H6: wet season | I6: موسم الأمطار
C7: season phase | D7: Growth | E7: النمو | F7: Indicate the phase of the season at the time of data collection. If the harvest from the season has not yet occurred, the question on crop harvest (crp_harv_change) will include the word “expected” (where #expected or nothing# is located). If the harvest has occured, "expected" will not be inserted in the question. | G7: حدد مرحلة الموسم في وقت جمع البيانات. إذا لم يتم الحصاد من الموسم بعد ، فإن السؤال عن حصاد المحاصيل (crp_harv_change) سيتضمن كلمة "متوقع" (حيث يوجد # متوقع أو لا شيء #). إذا تم الحصاد ، لن يتم إدخال "متوقع" في السؤال . | H7: Harvesting | I7: الحصاد
C8: local measurement unit | D8: 5)Labneh 6)Qassabh 7)Hablah 8)Ma'ad 9)Salook 10)Shaklah 11)Neiha 12)Matreh 13)Wadan 14)Oqum 15)Asaoo 16)Shagan 17)Arfad 18)Aber 19)Taleem 20)Magabi 21)Hediah 22)Thera'a 23)Materah | E8: 5)لبنة 6)قصبة 7) حبل/حبلة 8) معاد 9)سلوق 10) شكلة 11) نيحة 12) مطرح 13)ودن 14) عقم 15)اسعاو 16) شجن 17)رفد/ارفاد 19) عبر 20) تليم 21)مجابي 22) حدية 23) ذراع 24) مطبرة | F8: Specify the local measurement unit for land size, other than acres, hectares, square meters and square feet. If no other unit of measurement is needed, keep this cell blank. | G8: حدد وحدة القياس المحلية لمساحة الأرض ، بخلاف الفدان والهكتار والمتر المربع والقدم المربع. إذا لم تكن هناك حاجة إلى وحدة قياس أخرى ، احتفظ بهذه الخلية فارغة. | H8: Jeribs | I8: جريب
C9: local measurement unit conversion | F9: Include the conversion of the local measurement unit to hectares. In other words, how many local measurement units are in 1 ha. Only digits in Latin numbers should be inputted. | G9: قم بتضمين تحويل وحدة القياس المحلية إلى هكتار. بمعنى آخر ، إلى كم هو عدد وحدات القياس المحلية في هكتار واحد. يرجى إدخال الأرقام في الأبجدية اللاتينية (...3, 2, 1). | H9: 0.2 | I9: 0.2
B10: FOR OPTIONAL QUESTIONS . (Fill out if applicable) . | C10: currency | D10: Rial | E10: الريال | F10: The name of the main currency used nationally; USD; Naira; Rial; Pesos; etc. | G10: اسم العملة الرئيسية المستخدمة وطنيا ؛ دولار أمريكي؛ نيرة؛ الريال؛ بيزو؛ إلخ. | H10: Naira | I10: نيرة
C11: MIN AMOUNT | D11: Not applicable | E11: Not applicable | F11: The minimum amount for an income source should be set at 0 or any value below which it is not possible to do a transaction. For example, the smallest coin/banknote in a currency can be 1000, in which case you would set the minimum at 1000. Provide this input in the same currency as specified above. Only digits in Latin numbers should be inputted. | G11: يجب تعيين الحد الأدنى لمبلغ مصدر الدخل على 0 أو أي قيمة أقل منها لا يمكن إجراء معاملة. على سبيل المثال ، يمكن أن تكون أصغر عملة / ورقة نقدية في عملة ما هي 1000 ، وفي هذه الحالة يمكنك تعيين الحد الأدنى عند 1000. يجب أن يكون هذا المبلغ بنفس العملة المحددة في الصف أعلاه. يرجى إدخال الأرقام في الأبجدية اللاتينية (...3, 2, 1). | H11: 5 | I11: 5
C12: MAX AMOUNT | D12: Not applicable | E12: Not applicable | F12: Set the maximum amount for an income source over 3 months. Enumerators will not be able to input values above this amount in questions related to income amounts. Using previous representative surveys for this population, you can estimate this amount by using the mean income plus five (5) standard deviations, unless the country has high inflation. In the latter case, set the maximum value based on your country context (higher than the proposed approach). Provide this input in the same currency as specified above. Only digits in Latin numbers should be inputted. | G12: حدد الحد الأقصى لمبلغ مصدر الدخل على مدى 3 أشهر. لن يتمكن جامعي البيانات من إدخال قيم أعلى من هذا المبلغ في الأسئلة المتعلقة بمبالغ الدخل. باستخدام المسوح التمثيلية السابقة لهذه الفئة من السكان ، يمكنك تقدير هذا المبلغ باستخدام متوسط ​​الدخل بالإضافة إلى خمسة انحرافات معيارية ما لم يكن هناك تضخم مرتفع في الدولة. في الحالة الأخيرة ، قم بتعيين الحد الأقصى للقيمة بناءً على سياق بلدك (أعلى من النهج المقترح). يجب أن يكون هذا المبلغ بنفس العملة المحددة أعلاه. يرجى إدخال الأرقام في الأبجدية اللاتينية (...3, 2, 1). | H12: 5000000 | I12: 5000000
C13: THRESHOLD | D13: Not applicable | E13: Not applicable | F13: The threshold salary should be calculated to flag outliers (responses that look suspiciously high). Using previous representative surveys for this population, a good estimate is the average plus three (3) standard deviations, which should give the threshold for the 3 or 4% highest income values. Provide this input in the same currency as specified above. Only digits in Latin numbers should be inputted. | G13: يجب حساب قيمة العتبة للراتب لتحديد القيم المتطرفة (الاستجابات التي تبدو مرتفعة بشكل مثير للريبة). باستخدام المسوح التمثيلية السابقة لهذه الفئة من السكان ، فإن التقدير الجيد هو المتوسط ​​زائد ثلاثة انحرافات معيارية ، والذي يجب أن يعطي قيمة العتبة لقيم الدخل الأعلى بنسبة 3 أو 4٪. يجب أن يكون هذا المبلغ بنفس العملة المحددة أعلاه. يرجى إدخال الأرقام في الأبجدية اللاتينية (...3, 2, 1). | H13: 1200000 | I13: 1200000
C14: local vegetables | D14: tomatoes, okra, zucchini, cauliflower, cucumber, onions | E14: طماطم ، بامية ، كوسة ، قرنييط (زهرة) ، خيار ، بصل | F14: Input some common local vegetables [to be used as examples in the food consumption score indicator]. | G14: أدخل بعض الخضروات المحلية الشائعة [لاستخدامها كأمثلة في مؤشر درجة استهلاك الغذاء]. | H14: eggplants, zucchini, cauliflower | I14: باذنجان ، كوسة ، قرنبيط
C15: local fruits | D15: apple, orange, banana, grapes, mango, papaya, fig, muskmelon, red watermelon, dates | E15: التفاح / البرتقال ، الموز ، العنب ، المانجو ، البابايا ، التين ، الشمام ، البطيخ الاحمر ، البلح | F15: Input some common local fruits [to be used as examples in the food consumption score indicator]. | G15: أدخل بعض الفاكهة المحلية الشائعة [لاستخدامها كأمثلة في مؤشر درجة استهلاك الغذاء]. | H15: apples, bananas, oranges | I15: التفاح والموز والبرتقال
B17: FILL OUT FOR QUESTIONNAIRE DURATION ESTIMATION . | C17: Expected percentage of respondents cultivating crops | D17: 38.7% (Source: YEM10) | E17: 38.7% (Source: YEM10) | F17: If the survey is representative and has no quotas, write the proportion of rural households cultivating crops at country level, or if the survey follows a previous round with identical sample design, just report the percentage from the previous round. If you are using quotas, calculate the ratio of the quota over the minimum sample size at the level where the quota is implemented (so if you have a minimum sample size per strata of 110 with a quota of 100 crop producers, then it's 100/110 = 91% (the maximum you should write is 100%). | G17: إذا كان المسح تمثيليًا وليس له حصص نسبية ، فاكتب نسبة الأسر الريفية التي تزرع محاصيل على المستوى الوطني ، أو إذا كان المسح يتبع جولة سابقة بتصميم عينة متطابق ، فما عليك سوى الإبلاغ عن النسبة المئوية من الجولة السابقة. إذا كنت تستخدم نظام الحصص النسبية ، فاحسب نسبة الحصة إلى الحد الأدنى لحجم العينة على المستوى الذي يتم فيه تنفيذ الحصة (لذلك إذا كان لديك حد أدنى لحجم العينة لكل طبقة 110 مع حصة 100 منتج محصول ، فسيكون 100 / 110 = 91٪ (الحد الأقصى الذي يجب أن تكتبه هو 100٪). | H17: 0.91 | I17: 0.91
C18: Expected percentage of respondents raising livestock | D18: 44.7% (Source: YEM10) | E18: 44.7% (Source: YEM10) | F18: If the survey is representative and has no quotas, write the proportion of rural households raising livestock at country level, or if the survey follows a previous round with identical sample design, just report the percentage from the previous round. If you are using quotas, calculate the ratio of the quota over the minimum sample size at the level where the quota is implemented (so if you have a minimum sample size of 110 but a quota of 100 livestock producers, then it's 100/110 = 91% (the maximum you should write is 100%) | G18: إذا كان المسح تمثيليًا وليس له حصص نسبية ، فاكتب نسبة الأسر الريفية التي تربي الماشية على المستوى الوطني ، أو إذا كان المسح يتبع جولة سابقة بتصميم عينة متطابق ، فما عليك سوى الإبلاغ عن النسبة المئوية من الجولة السابقة. إذا كنت تستخدم نظام الحصص النسبية ، فاحسب نسبة الحصة إلى الحد الأدنى لحجم العينة على المستوى الذي يتم فيه تنفيذ الحصة (لذلك إذا كان لديك حد أدنى لحجم العينة لكل طبقة 110 مع حصة 100 مربي الماشية ، فسيكون 100 / 110 = 91٪ (الحد الأقصى الذي يجب أن تكتبه هو 100٪). | H18: 0.91 | I18: 0.91
C19: Expected percentage of respondents involved in fishery | D19: 2% (Source: YEM10) | E19: 2% (Source: YEM10) | F19: If the survey is representative and has no quotas, write the proportion of rural households involved in fisheries or aquaculture, otherwise if you are using quotas, calculate the ratio of the quota over the sample size at the level where the quota is implemented. (so if you haven't set a quota, and you expect to have a representative proportion of fishermen, just write the percentage of fishermen in the population you are targeting, in the example to the right, 5%) | G19: إذا كان المسح تمثيليًا وليس له حصص نسبية ، فاكتب نسبة الأسر الريفية العاملة في مصايد الأسماك أو تربية الأحياء المائية على المستوى الوطني. وإلا إذا كنت تستخدم الحصص النسبية ، فاحسب نسبة الحصة إلى حجم العينة على المستوى الذي يتم فيه تنفيذ الحصة. (لذلك إذا لم تحدد حصة ، وكنت تتوقع أن يكون لديك نسبة تمثيلية من الصيادين ، فاكتب فقط النسبة المئوية للصيادين من السكان الذين تستهدفهم ، في المثال على اليمين ، 5٪). | H19: 0.05 | I19: 0.05

Sheet Admin 2 info
A1: adm2_name | B1: adm2_name_local | C1: adm2_pcode | D1: adm1_name | E1: adm1_pcode | F1: adm0_name | G1: adm0_ISO3
A2: Ar Radmah | B2: الرضمة | C2: YE1103 | D2: Ibb | E2: YE11 | F2: Yemen | G2: YEM
A3: An Nadirah | B3: النادرة | C3: YE1104 | D3: Ibb | E3: YE11 | F3: Yemen | G3: YEM
A4: Ash Sha'ir | B4: الشعر | C4: YE1105 | D4: Ibb | E4: YE11 | F4: Yemen | G4: YEM
A5: Sibah | B5: سباح | C5: YE1205 | D5: Abyan | E5: YE12 | F5: Yemen | G5: YEM
A6: As Saddah | B6: السدة | C6: YE1106 | D6: Ibb | E6: YE11 | F6: Yemen | G6: YEM
A7: Al Makhadir | B7: المخادر | C7: YE1107 | D7: Ibb | E7: YE11 | F7: Yemen | G7: YEM
A8: Hubaysh | B8: حبيش | C8: YE1108 | D8: Ibb | E8: YE11 | F8: Yemen | G8: YEM
A9: Far Al Udayn | B9: فرع العدين | C9: YE1110 | D9: Ibb | E9: YE11 | F9: Yemen | G9: YEM
A10: Al Udayn | B10: العدين | C10: YE1111 | D10: Ibb | E10: YE11 | F10: Yemen | G10: YEM
A11: Jiblah | B11: جبلة | C11: YE1112 | D11: Ibb | E11: YE11 | F11: Yemen | G11: YEM
A12: Ba'dan | B12: بعدان | C12: YE1113 | D12: Ibb | E12: YE11 | F12: Yemen | G12: YEM
... A334: Al Qafr | B334: القفر | C334: YE1101 | D334: Ibb | E334: YE11 | F334: Yemen | G334: YEM
