Workbook

Sheet survey
A1: GeoPoll Submission Form
A2: FAO - Household Questionnaire | S2: Additional notes
A3: Q # | B3: Q Name | C3: Suggested Qname | D3: English | E3: Length | F3: fr_French | G3: Length | H3: sw_Swahili | I3: Length | J3: Q Type | K3: Randomize | L3: Conditional | M3: Programming Instructions | N3: Codes | O3: Skip Pattern | P3: GeoPoll Comments | Q3: Default skip patterns & conditional | R3: Specify skip pattern variable | T3: Estimated percentage of repondents | W3: Mandatory | AA3: Duration | AB3: Weighted duration | AC3: Core questions only
A4: A. PRESENTATION OF THE SURVEY AND ELIGIBILITY CRITERIA SELECTION | W4: no | AB4: =IF(AA4="","",AA4*Y4) | AC4: =IF(W4="yes",AB4,"")
A5: NA | B5: Optin | D5: Optin | E5: =LEN(D5) | F5: Optin | G5: =LEN(F5) | H5: optin | I5: =LEN(H5) | J5: Open Ended | K5: NA | L5: NA | M5: Form Type - TextBox | N5: NA | O5: Any Response = calldispo | Q5: NA | W5: no | AA5: 0 | AB5: =IF(AA5="","",AA5*T5) | AC5: =IF(W5="yes",AB5,"")
A6: NA | B6: calldispo | C6: calldispo | D6: Phone number: #CATI_MOBILENUMBER# 1)Someone answers 2)No answer 3)Refusal 4)Call back 5)Non-Working Number | E6: =LEN(D6) | F6: Numéro de téléphone: #CATI_MOBILENUMBER# 1)Quelqu’un répond 2)Pas de réponse 3)Refuse 4)Doit être rappelé 5)Numéro non fonctionnel | G6: =LEN(F6) | H6: Nambari ya simu: #CATI_MOBILENUMBER# 1)Mtu ana jibu 2)Hakuna jibu 3)Kukatala 4)Piga simu tena 5)Namba isiyofanya kazi | I6: =LEN(H6) | J6: Single Choice | K6: NA | L6: NA | M6: Form Type - Buttons | N6: NA | O6: 1 = resp_language 2 = NoAnswer 3 = Refusal 4 = WhenCallBack 5 = NonWorkingNumber | Q6: NA | W6: no | AA6: 14.695308 | AB6: =IF(AA6="","",AA6*T6) | AC6: =IF(W6="yes",AB6,"")
A7: NA | B7: NoAnswer | C7: calldispo_noanswer | D7: Phone rang and no one answered. Inclusive of voicemail, answering machine and temporary issues with network connection. | E7: =LEN(D7) | F7: Le téléphone a sonné et personne n'a répondu. Y compris la messagerie vocale, le répondeur et les problèmes temporaires de connexion au réseau. | G7: =LEN(F7) | H7: Simu iliita na hakuna wa ku pokea. | I7: =LEN(H7) | J7: NA | K7: NA | L7: NA | M7: NA | N7: NA | O7: End Poll NoAnswer | Q7: NA | W7: no | AA7: 0 | AB7: =IF(AA7="","",AA7*T7) | AC7: =IF(W7="yes",AB7,"")
A8: NA | B8: NonWorkingNumber | C8: calldispo_NonWorkingNumber | D8: Phone number is not in service, not working, or not valid. | E8: =LEN(D8) | F8: Le numéro de téléphone n'est pas en service, ne fonctionne pas ou n'est pas valide. | G8: =LEN(F8) | H8: Simu ilikata au haikutumike. | I8: =LEN(H8) | J8: NA | K8: NA | L8: NA | M8: NA | O8: End Poll NonWorkingNumber | Q8: NA | R8: NA
A9: NA | B9: resp_language | C9: resp_language | D9: Which language do you wish to proceed with? [OPERATOR: READ ANSWER CHOICES. SINGLE RESPONSE.] 1)English 2)French 3)Swahili | E9: =LEN(D9) | F9: Quelle langue souhaitez-vous utiliser? [OPÉRATEUR/OPÉRATRICE: LIRE LES CHOIX, RÉPONSE UNIQUE] 1)Anglais 2)Français 3)Swahili | G9: =LEN(F9) | H9: Unataka kuendelea na lugha gani? [OPERATOR: SOMA MAJIBU. CHAGUA JIBU MOJA.] 1)English 2)Kifaransa 3)Kiswahili | I9: =LEN(H9) | J9: Single Choice | K9: NA | L9: NA | M9: Form Type - Buttons | N9: NA | O9: 1 = introduction [English] 2 = introduction [French] 3 = introduction [Swahili] | Q9: For any response, go to introduction | S9: Insert most common national languages here [max 4 for translation with GeoPoll]. | W9: no | AA9: 3.1032724 | AB9: =IF(AA9="","",AA9*T9) | AC9: =IF(W9="yes",AB9,"")
A10: NA | B10: introduction | C10: introduction | D10: Hello sir/ma'am, my name is #OPERATOR#, and I am calling from GeoPoll Polling Agency on behalf of the Food and Agriculture Organization of the United Nations [FAO]. We are conducting a survey on household livelihoods and the ability to access food in your area. I would like to ask you some questions about your household. The survey usually takes 20-30 minutes to complete. Any information that you provide will be kept strictly confidential, only used for the purpose of the survey and will not be shown to other people. Your voluntary participation in the outcome of this interview is NOT IN ANY WAY linked to your personal chance of receiving any assistance. This is voluntary and you can choose not to answer any or all of the questions if you want. However, we hope that you will participate since your views are important. You will receive #TOPUP#! of communication credit as an incentive for the participation of the survey. Please note that this call may be recorded for quality purposes. Do you have any questions? [OPERATOR: ADDRESS QUESTIONS FROM RESPONDENT, IF ANY.] 1)CONTINUE | E10: =LEN(D10) | F10: Bonjour Monsieur/Madame, mon nom est #OPERATOR#. Je vous appelle de la part de l'agence de sondage GeoPoll pour le compte de l'Organisation des Nations Unies pour l'alimentation et l'agriculture [la FAO]. Nous menons une enquête sur les moyens d'existence et la capacité des ménages à accéder à la nourriture dans votre région. J'aimerais vous poser quelques questions sur votre ménage. L'enquête dure généralement entre 20-30 minutes. Toutes les informations que vous fournirez resteront strictement confidentielles; elles ne seront utilisées que dans le cadre de cette enquête et ne seront pas communiquées à d'autres personnes. Votre participation volontaire à cet entretien n'est en AUCUN CAS liée à la possibilité de recevoir une quelconque aide. Votre participation est volontaire et, si vous le souhaitez, vous pouvez choisir de ne pas répondre à une partie ou à la totalité des questions. Cependant, nous espérons que vous voudrez bien participer car votre avis est important. Vous recevrez #TOPUP#! de crédit téléphonique comme incitation à participer à l'enquête. Veuillez noter que cet appel peut être enregistré à des fins de contrôle qualité. Avez-vous des questions? [OPÉRATEUR/OPÉRATRICE: LE CAS ÉCHÉANT, RÉPONDRE AUX QUESTIONS DE LA PERSONNE INTERROGÉE.] 1)CONTINUER | G10: =LEN(F10) | H10: Habari bwana/mama, jina langu ni #OPERATOR#, napiga simu kutoka Shirika la Kupigia Kura la GeoPoll kwa niaba ya Shirika la Chakula na Kilimo la Umoja wa Mataifa [FAO]. Tunafanya utafiti kuhusu maisha ya kaya na uwezo ya kupata chakula katika eneo lako.Nilipenda kukuuliza baadhi ya maswali kuhusu kaya yako. Utafiti kwa kawaida huchukua dakika 20-30 kukamilika. Taarifa yote uta peleka itawekwa kwa siri kabisa, itatumika tu kwa madhumuni ya utafiti na haitaonyeshwa kwa watu wengine. Kushiriki kwako kwa hiari katika matokeo ya mahojiano haya HAUKUHUSIWI KWA NJIA YOYOTE na nafasi yako ya kibinafsi ya kupokea usaidizi wowote. Hili ni la hiari na unaweza kuchagua kutojibu yote au maswali yote ikiwa unataka. Hata hivyo, tunatumai kuwa utashiriki kwa kuwa maoni yako ni muhimu. Utapokea #TOPUP#! mikopo ya mawasiliano kama motisha ya ushiriki wa utafiti. Tafadhali kumbuka kuwa simu hii inaweza kurekodiwa kwa madhumuni ya ubora. Una maswali ? [OPERATOR: ANWANI MASWALI KUTOKA KWA MTAJIWA, IKIWA YAPO.] 1)ENDELEA | I10: =LEN(H10) | J10: Single Choice | K10: NA | L10: NA | M10: Form Type - Buttons | N10: NA | O10: 1 = Agree | Q10: For any response, go to Agree | S10: Set the amount of incentive here, if any. | W10: no | AA10: 37.418449 | AB10: =IF(AA10="","",AA10*T10) | AC10: =IF(W10="yes",AB10,"")
A11: NA | B11: Agree | C11: resp_agree | D11: Are you interested in participating in this survey? [OPERATOR: SINGLE RESPONSE] 1)Yes 2)Not now but another time in the week 3)No | E11: =LEN(D11) | F11: Souhaitez-vous participer à cette enquête? [OPÉRATEUR/OPÉRATRICE: RÉPONSE UNIQUE] 1)Oui 2)Pas maintenant mais à un autre moment de la semaine 3)Non | G11: =LEN(F11) | H11: Una nia ya kushiriki katika utafiti huu?_x000D_ _x000D_ [OPERATOR: JIBU MOJA]_x000D_ _x000D_ 1)Ndiyo_x000D_ 2)Sio sasa lakini wakati mwingine katika wiki_x000D_ 3)Hapana | I11: =LEN(H11) | J11: StartRecording | K11: NA | L11: NA | M11: Form Type - Buttons | N11: NA | O11: 1 = id_panel 2 = WhenCallBack 3 = resp_refusalwhy | Q11: if Agree = 1, go to id_panel OR resp_firstname if Agree = 2, go to WhenCallBack if Agree = 3, go to resp_refusalwhy | S11: It is highly recommended to include the question id_panel if a panelist approach is used. | T11: 1 | W11: no | AA11: 3.8059516 | AB11: =IF(AA11="","",AA11*T11) | AC11: =IF(W11="yes",AB11,"")
A12: NA | B12: id_panel | C12: id_panel | D12: Have you or any member of your household received a call on behalf of FAO regarding this topic in the past two years? [OPERATOR: SINGLE RESPONSE.] 1)YES 2)NO 3)DON'T KNOW | E12: =LEN(D12) | F12: Est-ce que vous ou un membre de votre ménage avez reçu un appel pour le compte de la FAO sur ce sujet au cours des deux dernières années? [OPÉRATEUR/OPÉRATRICE: RÉPONSE UNIQUE] 1)OUI 2)NON 3)NE SAIT PAS | G12: =LEN(F12) | H12: Je, wewe au mwanachama yeyote wa familia yako mmepokea simu kwa niaba ya FAO kuhusu mada hii katika miaka miwili iliyopita? [OPERATOR: JIBU MOJA.] 1)NDIYO 2)HAPANA 3)SIJUE | I12: =LEN(H12) | J12: Single Choice | K12: NA | L12: NA | M12: Form Type - Buttons | N12: NA | O12: 1-3 = resp_firstname | Q12: For any response, go to resp_firstname | T12: 1 | W12: no
A13: NA | B13: resp_refusalwhy | C13: resp_refusalwhy | D13: Please let us know why you have REFUSED to take the survey. [OPERATOR: SINGLE RESPONSE] 1)Not interested 2)Do not want to be recorded 3)Other [specify] | E13: =LEN(D13) | F13: Pourriez-vous m'indiquer pourquoi vous refusez de répondre à l'enquête. [OPÉRATEUR/OPÉRATRICE: RÉPONSE UNIQUE] 1)Pas intéressé 2)Ne veut pas être enregistré 3)Autre [préciser] | G13: =LEN(F13) | H13: Tafadhali tufahamishe kwa nini UMEKUKATALA kufanya uchunguzi. [OPERATOR: JIBU MOJA] 1)Sipendezwi 2)Sitaki kurekodiwa 3)Yingine [taja] | I13: =LEN(H13) | J13: Open Ended-Single Choice | K13: NA | L13: NA | M13: Form Type - RadioList | N13: NA | O13: 1-3 = Refusal | Q13: For any response, go to Refusal | T13: 1 | W13: no | AA13: 0 | AB13: =IF(AA13="","",AA13*T13) | AC13: =IF(W13="yes",AB13,"")
A14: NA | B14: WhenCallBack | C14: resp_whencallback | D14: When would it be a good time to call you back? [RECORD HH/MM/DD/MM OF CALLBACK] | E14: =LEN(D14) | F14: À quel moment pourrais-je vous rappeler? [ENREGISTRER HH/MM/JJ/MM DU RAPPEL] | G14: =LEN(F14) | H14: Ni wakati gani mzuri wa kukupigia simu tena?_x000D_ _x000D_ [REKODI HH/MM/DD/MM WA KUPIGIWA SIMU] | I14: =LEN(H14) | J14: Open Ended | K14: NA | L14: NA | M14: Form Type - TextBox IsCallBackDemographic | N14: NA | O14: Any Response = CallbackMessageEN | Q14: For any response, go to CallbackMessageEN | T14: 1 | W14: no | AA14: 0 | AB14: =IF(AA14="","",AA14*T14) | AC14: =IF(W14="yes",AB14,"")
A15: NA | B15: CallbackMessageEN | C15: callbackmessage_en | D15: Thank you, we will call you back at {WhenCallBack} you requested. Thank you again and have a great day! [OPERATOR: ENTER CALL NOTES BELOW, WHO YOU SPOKE TO AND WHAT THEY SAID] | E15: =LEN(D15) | F15: Merci, nous vous rappellerons à {WhenCallBack}. Merci encore et bonne journée! [OPÉRATEUR/OPÉRATRICE: SAISIR LES DONNÉES D'APPEL CI-DESSOUS, LE NOM DE LA PERSONNE À LAQUELLE VOUS AVEZ PARLÉ ET CE QU'ELLE A DIT] | G15: =LEN(F15) | H15: Asante, tutakupigia tena kwa {WhenCallBack} uliyoomba. Asante tena na siku njema kwako! [OPERATOR: WEKA MAELEZO YA SIMU HAPA CHINI, NANI ULIONGEA NAYE NA WALICHOSEMA] | I15: =LEN(H15) | J15: Open Ended | K15: NA | L15: NA | M15: Form Type - TextBox | N15: NA | O15: Any Response = End poll callback | Q15: NA | T15: 1 | W15: no | AA15: 0 | AB15: =IF(AA15="","",AA15*T15) | AC15: =IF(W15="yes",AB15,"")
A16: NA | B16: Ineligible | C16: NA | D16: You are ineligible for this survey. Thank you for your time and please look out for future surveys! | E16: =LEN(D16) | F16: Vous êtes inéligible pour participer à cette enquête. Merci pour votre temps et renseignez-vous sur les prochains sondages! | G16: =LEN(F16) | H16: Hujastahiki utafiti huu. Asante kwa muda wako na tafadhali angalia tafiti zijazo! | I16: =LEN(H16) | J16: NA | K16: NA | L16: NA | M16: NA | N16: NA | O16: End Poll Ineligible | Q16: NA | T16: 1 | W16: no | AA16: 0 | AB16: =IF(AA16="","",AA16*T16) | AC16: =IF(W16="yes",AB16,"")
A17: NA | B17: Refusal | C17: NA | D17: Thank you for your time, you will be removed from today's survey. | E17: =LEN(D17) | F17: Merci pour votre temps. Vous allez être retiré de l'enquête d'aujourd'hui. | G17: =LEN(F17) | H17: Asante kwa muda wako, utaondolewa kwenye utafiti wa leo. | I17: =LEN(H17) | J17: NA | K17: NA | L17: NA | M17: NA | N17: NA | O17: End poll declined | Q17: NA | T17: 1 | W17: no | AA17: 0 | AB17: =IF(AA17="","",AA17*T17) | AC17: =IF(W17="yes",AB17,"")
A18: B. GENERAL INFORMATION & ELIGIBILITY CRITERIA | AB18: =IF(AA18="","",AA18*T18) | AC18: =IF(W18="yes",AB18,"")
A19: 1 | B19: resp_firstname | C19: resp_firstname | D19: What is your first name? [OPERATOR: RECORD THE RESPONDENT'S FIRST NAME. ENTER 999 FOR REFUSED.] | E19: =LEN(D19) | F19: Quel est votre prénom? [OPÉRATEUR/OPÉRATRICE: SAISIR LE PRÉNOM DE LA PERSONNE INTÉRROGÉE. SAISIR 999 POUR REFUSÉ.] | G19: =LEN(F19) | H19: Jina lako la jamii ni nani? [OPERETERA: REKODI JINA YA KWANZA YA MUJIBU. INGIZA 999 KWA KUKATALA.] | I19: =LEN(H19) | J19: Open Ended | K19: NA | L19: NA | M19: Form Type - TextBox | N19: NA | O19: Any Response = resp_lastname | Q19: For any response, go to resp_lastname | T19: =1 | W19: yes | AA19: 25.874027 | AB19: =IF(AA19="","",AA19*T19) | AC19: =IF(W19="yes",AB19,"")
A20: 2 | B20: resp_lastname | C20: resp_lastname | D20: What is your last name? [OPERATOR: RECORD THE RESPONDENT'S LAST NAME. ENTER 999 FOR REFUSED.] | E20: =LEN(D20) | F20: Quel est votre nom de famille? [OPÉRATEUR/OPÉRATRICE: SAISIR LE NOM DE FAMILLE DE LA PERSONNE INTÉRROGÉE. SAISIR 999 POUR REFUSÉ.] | G20: =LEN(F20) | H20: Jina lako ya mwisho ni nani?_x000D_ _x000D_ [OPERETERA: REKODI JINA LA MWISHO YA MUDIBU. INGIZA 999 KWA KUKATALA.] | I20: =LEN(H20) | J20: Open Ended | K20: NA | L20: NA | M20: Form Type - TextBox | N20: NA | O20: Any Response = resp_age | Q20: For any response, go to resp_age | T20: =1 | W20: yes | AA20: 8.5994816 | AB20: =IF(AA20="","",AA20*T20) | AC20: =IF(W20="yes",AB20,"")
A21: 3 | B21: resp_age | C21: resp_age | D21: How old are you? [OPERATOR: RECORD AGE IN NUMBER OF YEARS. ROUND UP TO NEAREST WHOLE NUMBER. IF THE RESPONDENT GIVES BIRTH YEAR, REPEAT THE QUESTION. ENTER 00 FOR DON'T KNOW.] | E21: =LEN(D21) | F21: Quel âge avez-vous [en années]? [OPÉRATEUR/OPÉRATRICE: SAISIR L'ÂGE EN ANNÉES. ARRONDIR AU NOMBRE ENTIER LE PLUS PROCHE. SI LE RÉPONDANT DONNE SON ANNÉE DE NAISSANCE, RÉPÉTER LA QUESTION. SAISIR 00 POUR "NE SAIT PAS".] | G21: =LEN(F21) | H21: Una miaka mingapi?_x000D_ _x000D_ [OPERATOR: REKODI UMRI KATIKA IDADI YA MIAKA. ZUNGUSHA HADI NAMBA NZIMA KARIBU. IKIWA MHOJIWA AMEJIFUNGUA MWAKA WA KUZALIWA, RUDIA SWALI. INGIA 00 KWA SIJUE.] | I21: =LEN(H21) | J21: Range | K21: NA | L21: NA | M21: Form Type - TextBox | N21: NA | O21: 0-17 = Ineligible 18-100 = resp_gender 00 = Ineligible | Q21: Only respondents from 18-100 will be eligible for the survey. | T21: =1 | W21: yes | AA21: 9.8907185 | AB21: =IF(AA21="","",AA21*T21) | AC21: =IF(W21="yes",AB21,"")
A22: =A21+1 | B22: resp_gender | C22: resp_gender | D22: What is the gender of the respondent? [OPERATOR: DO NOT ASK THIS QUESTION OUT LOUD. LISTEN TO THE VOICE AND SELECT THE GENDER.] 1)Male 2)Female 3)DON'T KNOW 4)REFUSED | E22: =LEN(D22) | F22: Quel est le sexe du répondant? [OPÉRATEUR/OPÉRATRICE: NE PAS POSER CETTE QUESTION À VOIX HAUTE. ÉCOUTER LA VOIX ET DÉTERMINER LE SEXE.] 1)Homme 2)Femme 3)NE SAIT PAS 4)REFUSÉ | G22: =LEN(F22) | H22: Jinsia ya mujibu ni nini?_x000D_ _x000D_ [OPERATOR: USIULIZE SWALI HILI KWA SAUTI. SIKILIZA SAUTI NA UCHAGUE JINSIA.]_x000D_ _x000D_ 1)Mwanaume_x000D_ 2)Mwanamke_x000D_ 3)SIJUE_x000D_ 4)KUKATALA | I22: =LEN(H22) | J22: Single Choice | K22: NA | L22: NA | M22: Form Type - Buttons | N22: NA | O22: 1-4 = phone_number_conf | Q22: For any response, go to phone_number_conf | T22: =1 | W22: yes | AA22: 1.7156482 | AB22: =IF(AA22="","",AA22*T22) | AC22: =IF(W22="yes",AB22,"")
A23: =A22+1 | B23: phone_number_conf | C23: phone_number_conf | D23: Is the phone number I am calling you on yours or a household members? [OPERATOR: SINGLE RESPONSE.] 1)YES 2)NO 3)DON'T KNOW 4)REFUSED | E23: =LEN(D23) | F23: Le numéro de téléphone sur lequel je vous appelle est-il le vôtre ou celui d'un membre de votre famille? [OPÉRATEUR/OPÉRATRICE: RÉPONSE UNIQUE.] 1)OUI 2)NON 3)NE SAIT PAS 4)REFUSÉ | G23: =LEN(F23) | H23: Je, namba ya simu nina kupigia ni yako au ni ya moja wa jamii yako? [OPERATOR: JIBU MOJA.] 1)NDIYO 2)HAPANA 3)SIJUE 4)KUKATALA | I23: =LEN(H23) | J23: Single Choice | K23: NA | L23: NA | M23: Form Type - Buttons | N23: NA | O23: 1 = contact_2 2 = phone_number_personal 3-4 = contact_2 | Q23: if phone_number_conf = 1, go to contact_2 if phone_number_conf = 2, go to phone_number_personal if phone_number_conf = 3-4, go to contact_2 | T23: =1 | W23: yes - panel | AA23: 6.375237 | AB23: =IF(AA23="","",AA23*T23) | AC23: =IF(W23="yes",AB23,"")
A24: =A23+1 | B24: phone_number_personal | C24: phone_number_pers | D24: What is your phone number? [OPERATOR: RECORD THE NUMBER GIVEN] | E24: =LEN(D24) | F24: Quel est votre numéro de téléphone? [OPÉRATEUR/OPÉRATRICE: SAISIR LE NUMERO.] | G24: =LEN(F24) | H24: Namba ya simu yako iko je?_x000D_ _x000D_ [OPERATOR: REKODI NAMBA ANA PELEKA] | I24: =LEN(H24) | J24: Range | K24: NA | L24: NA | M24: Form Type - TextBox | N24: NA | O24: 1000000-999999999999 = contact_2 | Q24: For any response, go to contact_2 | T24: =1 | W24: yes - panel | AA24: 28.700001 | AB24: =IF(AA24="","",AA24*T24) | AC24: =IF(W24="yes",AB24,"")
A25: =A24+1 | B25: contact_2 | C25: contact_2 | D25: Can you give me an additional phone number belonging to you, another household member or a close relation living outside of the household at which you can be reached? [OPERATOR: SINGLE RESPONSE.] 1)YES - mine 2)YES - other household member 3)YES - friend or relative [non-household member] 4)NO 5)DON'T KNOW 6)REFUSED | E25: =LEN(D25) | F25: Pouvez-vous me donner un numéro de téléphone supplémentaire, le vôtre, celui d'un autre membre du ménage ou d’un proche vivant en dehors du ménage, auquel vous pouvez être joint? [OPÉRATEUR/OPÉRATRICE: RÉPONSE UNIQUE.] 1)OUI - le mien 2)OUI - un autre membre du ménage 3)OUI - un ami ou un parent [non membre du ménage]. 4)NON 5)NE SAIT PAS 6)REFUSÉ | G25: =LEN(F25) | H25: Je, unaweza kunipa nambari nyingine ya simu inayomilikiwa na wewe, mwanachama mwingine wa familia yako, au ndugu aliye nje ya familia ambapo unaweza kupatikana? [MWENDESHAJI: JIBU MOJA.] 1)NDIYO – yangu 2)NDIYO – mwanakaya mwingine 3)Ndiyo – rafiki au jamaa [asiye mwanakaya] 4)HAPANA 5)SIJUE 6)NILIKUKATALA | I25: =LEN(H25) | J25: Single Choice | K25: NA | L25: NA | M25: Form Type - Buttons | N25: NA | O25: 1-3 = phone_number_2 4-6 = hh_admin1 | Q25: if contact_2 = 1-3, go to phone_number_2 if contact_2 = 4-6, go to contact_3 | T25: =1 | W25: yes - panel | AA25: 10.141817 | AB25: =IF(AA25="","",AA25*T25) | AC25: =IF(W25="yes",AB25,"")
A26: =A25+1 | B26: phone_number_2 | C26: phone_number_2 | D26: What is the additional phone number? [OPERATOR: RECORD THE NUMBER GIVEN] | E26: =LEN(D26) | F26: Quel est cet autre numéro de téléphone? [OPÉRATEUR/OPÉRATRICE: SAISIR LE NUMERO.] | G26: =LEN(F26) | H26: Nambari ya simu ingine ni nini?_x000D_ _x000D_ [OPERATOR: REKODI NAMBA ANA PELEKA] | I26: =LEN(H26) | J26: Range | K26: NA | L26: NA | M26: Form Type - TextBox | N26: NA | O26: 1000000-999999999999 = contact_2_name | Q26: For any response, go to contact_2_name | T26: =1 | W26: yes - panel | AA26: 21.659983 | AB26: =IF(AA26="","",AA26*T26) | AC26: =IF(W26="yes",AB26,"")
A27: =A26+1 | B27: contact_2_name | C27: contact_2_name | D27: What is the name of the contact? [OPERATOR: RECORD THE NAME OF THE CONTACT FOR THE PHONE NUMBER.] | E27: =LEN(D27) | F27: Quel est le nom du contact associé à ce numéro de téléphone? [OPÉRATEUR/OPÉRATRICE: SAISIR LENOM DU CONTACT POUR CE NUMERO DE TÉLÉPHONE.] | G27: =LEN(F27) | H27: Jina la mawasiliano ni nani? [OPERATOR: REKODI JINA LA ANAYEWASILIANA KWA NAMBA YA SIMU.] | I27: =LEN(H27) | J27: Open Ended | K27: NA | L27: Send if "contact_2" "Equals" "YES - other household member" Or "contact_2" "Equals" "YES - friend or relative [non-household member]" if not satisfied go to "contact_3" | M27: Form Type - TextBox | N27: NA | O27: Any Response = contact_3 | Q27: Asked if response to contact_2 was "YES - other household member" or "YES - friend or relative [non-household member]". Otherwise, it skips to "contact_3". For any response, go to contact_3 | T27: =1 | W27: yes - panel | AA27: 11.821796 | AB27: =IF(AA27="","",AA27*T27) | AC27: =IF(W27="yes",AB27,"")
A28: =A27+1 | B28: contact_3 | C28: contact_3 | D28: Can you give me an additional phone number belonging to you, another household member or a close relation living outside of the household at which you can be reached? [OPERATOR: SINGLE RESPONSE.] 1)YES - mine 2)YES - other household member 3)YES - friend or relative [non-household member] 4)NO 5)DON'T KNOW 6)REFUSED | E28: =LEN(D28) | F28: Pouvez-vous me donner un numéro de téléphone supplémentaire, le vôtre, celui d'un autre membre du ménage ou d’un proche vivant en dehors du ménage, auquel vous pouvez être joint? [OPÉRATEUR/OPÉRATRICE: RÉPONSE UNIQUE.] 1)OUI - le mien 2)OUI - un autre membre du ménage 3)OUI - un ami ou un parent [non membre du ménage]. 4)NON 5)NE SAIT PAS 6)REFUSÉ | G28: =LEN(F28) | H28: Je, unaweza kunipa nambari nyingine ya simu inayomilikiwa na wewe, mwanachama mwingine wa familia yako, au ndugu aliye nje ya familia ambapo unaweza kupatikana? [MWENDESHAJI: JIBU MOJA.] 1)NDIYO – yangu 2)NDIYO – mwanakaya mwingine 3)NDIYO – rafiki au jamaa [asiye mwanakaya] 4)HAPANA 5)SIJUE 6)NILIKUKATALA | I28: =LEN(H28) | J28: Single Choice | K28: NA | L28: NA | M28: Form Type - Buttons | N28: NA | O28: 1-3= phone_number_3 4-6 = hh_admin1 | Q28: if contact_3 = 1-3, go to phone_number_3 if contact_3 = 4-6, go to hh_admin1 | T28: =1 | W28: yes - panel | AA28: 3.163594 | AB28: =IF(AA28="","",AA28*T28) | AC28: =IF(W28="yes",AB28,"")
A29: =A28+1 | B29: phone_number_3 | C29: phone_number_3 | D29: What is the additional phone number? [OPERATOR: RECORD THE NUMBER GIVEN] | E29: =LEN(D29) | F29: Quel est cet autre numéro de téléphone? [OPÉRATEUR/OPÉRATRICE: SAISIR LE NUMERO.] | G29: =LEN(F29) | H29: Namba ya simu yako ingine ni nini? [OPERATOR: REKODI NAMBA ULIYOPEWA] | I29: =LEN(H29) | J29: Range | K29: NA | L29: NA | M29: Form Type - TextBox | N29: NA | O29: 1000000-999999999999 = contact_3_name | Q29: For any response, go to contact_3_name | T29: =1 | W29: yes - panel | AA29: 10.830144 | AB29: =IF(AA29="","",AA29*T29) | AC29: =IF(W29="yes",AB29,"")
A30: =A29+1 | B30: contact_3_name | C30: phone_number_3_name | D30: What is the name of the contact? [OPERATOR: RECORD THE NAME OF THE CONTACT FOR THE PHONE NUMBER.] | E30: =LEN(D30) | F30: Quel est le nom du contact associé à ce numéro de téléphone? [OPÉRATEUR/OPÉRATRICE: SAISIR LENOM DU CONTACT POUR CE NUMERO DE TÉLÉPHONE.] | G30: =LEN(F30) | H30: Jina la mawasiliano ni nani?_x000D_ _x000D_ [OPERATOR: REKODI JINA KUFUATANA NA NAMBA YA SIMU.] | I30: =LEN(H30) | J30: Open Ended | K30: NA | L30: Send if "contact_3" "Equals" "YES - other household member" Or "contact_3" "Equals" "YES - friend or relative [non-household member]" if not satisfied go to "hh_admin1" | M30: Form Type - TextBox | N30: NA | O30: Any Response = hh_admin1 | Q30: Asked if response to contact_3 was "YES - other household member" or "YES - friend or relative [non-household member]". Otherwise, it skips to "hh_admin1". For any response, go to hh_admin1 | T30: =1 | W30: yes - panel | AA30: 11.260417 | AB30: =IF(AA30="","",AA30*T30) | AC30: =IF(W30="yes",AB30,"")
A31: =A30+1 | B31: hh_admin1 | C31: hh_admin1 | D31: Currently, in which $ADMIN1$ does your household reside? [OPERATOR: SINGLE SELECTION.] [HINT: HOUSEHOLD CONSISTS OF ALL MEMBERS LIVING TOGETHER, SHARING RESOURCES & EATING FROM THE SAME POT.] 1)ADMIN1 2)DON'T KNOW 3)REFUSED | E31: =LEN(D31) | F31: Actuellement, dans quel $ADMIN1$ votre ménage vit-il? [OPÉRATEUR/OPÉRATRICE: RÉPONSE UNIQUE.] [NOTE: LE MÉNAGE EST COMPOSÉ DE TOUTES LES PERSONNES VIVANT ENSEMBLE, METTANT EN COMMUN LEURS RESSOURCES ET PARTAGEANT LEURS REPAS.] 1)ADMIN1 2)NE SAIT PAS 3)REFUSÉ | J31: Single Choice | K31: NA | L31: NA | M31: Form Type - Buttons IsDemographic - ADM1 | N31: NA | O31: 1 = Ineligible 2 = Ineligible 3 = Ineligible 4 = Ineligible 5 = Ineligible 6 = hh_admin2_6 7 = Ineligible 8 = Ineligible 9 = Ineligible 10 = Ineligible 11 = Ineligible 12 = Ineligible 13 = Ineligible 14 = Ineligible 15 = Ineligible 16 = Ineligible 17 = Ineligible 18 = Ineligible 19 = hh_admin2_19 20 = Ineligible 21 = Ineligible 22 = hh_admin2_22 23 = Ineligible 24 = hh_admin2_24 25 = Ineligible 26 = Ineligible 27-28 = Ineligible | T31: =1 | W31: yes | AA31: 13.957259 | AB31: =IF(AA31="","",AA31*T31) | AC31: =IF(W31="yes",AB31,"")
A32: =A31+1 | B32: hh_admin2_1 | C32: hh_admin2_6 | D32: Currently, in which $ADMIN2$ does your household reside? [OPERATOR: SINGLE RESPONSE.] 1)ADMIN2 2)DON'T KNOW 3)REFUSED | E32: =LEN(D32) | F32: Actuellement, dans quel $ADMIN2$ votre ménage vit-il? [OPÉRATEUR/OPÉRATRICE: RÉPONSE UNIQUE.] 1)ADMIN2 2)NE SAIT PAS 3)REFUSÉ | H32: Kaya yako iko Ku territoire/ville gani? [OPERATEUR/OPERATRICE: USISOME CHAGUZI. JIBU MOJA TU] 1)ARU 2)BUNIA 3)DJUGU 4)IRUMU 5)MAHAGI 6)MAMBASA 7)SIJUE 8)KUKATALA | J32: Single Choice | K32: NA | L32: NA | M32: Form Type - Dropdown IsDemographic - ADM2 | N32: NA | O32: 1-6 = quotareached 7-8 = Ineligible | P32: GeoPoll [5/6/2025]. Excluded the locations of ARIWARA, INGBOKOLO, and MONGWALU despite being within the Admin2 info sheet because they are not currently in the quota table and are locations within other existing territories. For example, Ariwara is a town in Aru territory. This is consistent with the approach taken during previous rounds. Kindly correct as needed. FAO: COnfirm to keep same choices as previous round. Thanks
A33: =A32+1 | B33: quotareached | C33: quotareached | D33: [OPERATOR: DO NOT READ. ANSWER QUESTION BELOW.] THIS RESPONDENT REPORTED THEY LIVE IN: {ADM1} {ADM2} 1)THE GOAL FOR THIS LOCATION HAS BEEN ACHIEVED - END SURVEY 2)THE GOAL FOR THIS LOCATION IS OPEN - CONTINUE SURVEY | E33: =LEN(D33) | F33: [OPÉRATEUR/OPÉRATRICE: NE PAS LIRE. RÉPONDRE À LA QUESTION CI-DESSOUS.] CE RÉPONDANT DIT VIVRE À: {ADM1} {ADM2} 1)L'OBJECTIF DANS CETTE ZONE A ÉTÉ ATTEINT - FIN DU SONDAGE 2)L'OBJECTIF DANS CETTE ZONE N'EST PAS ENCORE ATTEINT - CONTINUER LE SONDAGE | G33: =LEN(F33) | H33: [OPERATOR: USISOME. JIBU SWALI HAPA CHINI.]_x000D_ _x000D_ MUJIBU HUYU ALIRIPOTI WANAISHI:_x000D_ _x000D_ {ADM1}_x000D_ {ADM2}_x000D_ _x000D_ 1)LENGO YA ENEO HILI LIMEFIKIWA - MUSHIO YA UTAFUTI_x000D_ 2)LENGO YA ENEO HILI LIMEFUNGUA - ENDELEA UTAFITI | I33: =LEN(H33) | J33: Single Choice | K33: NA | L33: NA | M33: Form Type - Buttons | N33: NA | O33: 1 = End Poll Quota Reached 2 = hh_agricactivity
A34: =A33+1 | B34: hh_agricactivity | C34: hh_agricactivity | D34: Has anybody in your household produced crops or livestock for household consumption or for sale in the past 12 months, including household members currently away for transhumance? [OPERATOR: SINGLE RESPONSE. THIS IS THE MAIN SCREENING QUESTION.] [HINT FOR PROBING: Do you cultivate any plants to sale or consume? Do you raise any animals with the intent of selling or consuming them or their products like meat, milk, wool or leather? Is one of your household member currently away with cattle or other animals for transhumance?] 1)Yes - crop production 2)Yes - livestock production 3)Yes - both crop and livestock production 4)No 5)DON'T KNOW 6)REFUSED | E34: =LEN(D34) | F34: Est-ce que quelqu'un dans votre ménage a produit des cultures ou du bétail pour la consommation du ménage ou pour la vente au cours des 12 derniers mois, y compris des membres du ménage actuellement partis pour la transhumance? [OPÉRATEUR / OPÉRATRICE : RÉPONSE UNIQUE. IL S'AGIT DE LA PRINCIPALE QUESTION DE SÉLECTION.] [CONSEILS POUR PRÉCISER : Cultivez-vous des végétaux afin de les vendre ou de les consommer ? Élevez-vous des animaux afin de les vendre ou de les consommer, y compris les produits issus de l'élevage, comme la viande, le lait, la laine ou le cuir ? L'un des membres de votre ménage est-il actuellement parti avec du bétail pour la transhumance ?] 1)Oui - production végétale 2)Oui - production animale 3)Oui - production végétale et animale 4)Non 5)NE SAIT PAS 6)REFUSÉ | G34: =LEN(F34) | H34: Je, kuna mtu yote katika nyumba yako amezalisha mazao au mifugo kwa ajili ya matumizi ya kaya au kwa ajili ya kuuza katika kipindi cha miezi 12 iliyopita, ikiwa ni pamoja na wanakaya ambao hawapo kwa sasa kwa ajili ya kubadilisha ubinadamu? [OPERATOR: JIBU MOJA. HILI NDILO SWALI KUU LA UCHUNGUZI.] [DOKEZO LA KUJARIBU: Je, unalima mimea yoyote ili kuuza au kutumia? Je, unafuga wanyama wowote kwa nia ya kuuza au kula au bidhaa yako kama nyama, maziba, pamba au ngozi? Je, moja wa wanakaya wako kwa sasa yuko mbali na ngombe au wanyama wengine kwa ajili ya kubadilisha ubinadamu?] 1)Ndiyo - uzalishaji wa mazao 2)Ndiyo - uzalishaji wa mifugo 3)Ndiyo - uzalishaji wa mazao na mifugo 4)Hapana 5)SIJUE 6)KUKATALA | I34: =LEN(H34) | J34: Single Choice | K34: NA | L34: NA | M34: Form Type - Buttons | N34: NA | O34: 1-4 = hh_fish 5-6 = Ineligible | Q34: if hh_agricactivity = 1-4, go to resp_id or hh_fish. Otherwise, the respondent is ineligible. | T34: =1 | W34: yes | AA34: 24.410839 | AB34: =IF(AA34="","",AA34*T34) | AC34: =IF(W34="yes",AB34,"")
A35: =A34+1 | B35: hh_fish | C35: hh_fish | D35: Has anybody in your household been engaged in aquatic production [fish catch or aquaculture farming] for household consumption or for sales in the past 12 months? [OPERATOR: SINGLE RESPONSE.] [HINT FOR PROBING: It should not include sports fishing. It should be about production of aquatic products [fish catch or aquaculture farming] for household consumption or sales.] 1)YES 2)NO 3)DON'T KNOW 4)REFUSED | E35: 116 | F35: Quelqu'un dans votre ménage a-t-il été impliqué dans la production aquatique [prise de poisson ou aquaculture] pour la consommation du ménage ou pour la vente au cours des 12 derniers mois ? [OPÉRATEUR/OPÉRATRICE: RÉPONSE UNIQUE.] [CONSEIL LORS DU SONDAGE : cette question et réponse ne devraient pas inclure la pêche sportive. Il s'agit plutôt de la production de produits aquatiques [prise de poisson ou aquaculture] pour la consommation ou la vente des ménages.] 1)OUI 2)NON 3)NE SAIT PAS 4)REFUSÉ | G35: =LEN(F35) | H35: Je, kuna mtu yeyote katika familia yako ambaye amekuwa akijishughulisha na uzalishaji wa majini [kuvua samaki au ufugaji wa samaki] kwa matumizi ya familia au kwa mauzo katika kipindi cha miezi 12 iliyopita? [MWENDESHAJI: JIBU MOJA.] [KIASHIRIA CHA KUCHUNGUZA: Haipaswi kujumuisha uvuvi wa michezo. Inapaswa kuwa juu ya uzalishaji wa mazao ya majini [samaki wanaovuliwa au ufugaji wa samaki] kwa matumizi ya famille au mauzo.] 1)NDIYO 2)HAPANA 3)SIJUE 4)NILIKUKATALA | I35: =LEN(H35) | J35: Single Choice | K35: NA | L35: NA | M35: Form Type - Buttons | N35: NA | O35: 1-2 = resp_id 3-4 = Ineligible | Q35: if hh_fish = 1-2, go to resp_id. Otherwise, the respondent is ineligible. | S35: Use this question if the survey seeks to gather important information on fisheries and/or aquaculture in the country.
A36: B. GENERAL HOUSEHOLD INFORMATION | AB36: =IF(AA36="","",AA36*T36) | AC36: =IF(W36="yes",AB36,"")
A37: =A35+1 | B37: resp_id | C37: resp_id | D37: Are you the head of household? [OPERATOR: SINGLE RESPONSE.] 1)YES 2)NO 3)DON'T KNOW 4)REFUSED | E37: 96 | F37: Êtes-vous le chef de ménage? [OPÉRATEUR/OPÉRATRICE: RÉPONSE UNIQUE.] 1)OUI 2)NON 3)NE SAIT PAS 4)REFUSÉ | G37: =LEN(F37) | H37: Wewe ni mkuu wa nyumba? [OPERATOR: JIBU MOJA.] 1)NDIYO 2)HAPANA 3)SIJUE 4)KUKATALA | I37: =LEN(H37) | J37: Single Choice | K37: NA | L37: NA | M37: Form Type - Buttons | N37: NA | O37: 1 = hh_education 2-4 = hh_age | Q37: if resp_id = 1, go to hh_education. Otherwise, go to hh_gender. | T37: 1 | W37: yes | AA37: 10.5 | AB37: =IF(AA37="","",AA37*T37) | AC37: =IF(W37="yes",AB37,"")
A38: =A37+1 | B38: hh_age | C38: hh_age | D38: How old is the head of household? [OPERATOR: SINGLE RESPONSE.] 1)Under 18 2)18 to 40 3)41 to 65 4)Over 65 5)DON'T KNOW 6)REFUSED | E38: =LEN(D38) | F38: Quel âge a le chef de famille? [OPÉRATEUR/OPÉRATRICE: RÉPONSE UNIQUE.] 1)Moins de 18 ans 2)entre 18 et 40 ans 3)entre 41 et 65 ans 4)Plus de 65 ans 5)NE SAIT PAS 6)REFUSÉ | G38: =LEN(F38) | H38: Mkuu wa nyumba ana umri gani? [OPERATOR: JIBU MOJA.] 1)Chini ya miaka 18 2)18 hadi 40 3)41 hadi 65 4)Zaidi ya 65 5)SIJUE 6)KUKATALA | I38: =LEN(H38) | J38: Single Choice | K38: NA | L38: NA | M38: Form Type - Buttons | N38: NA | O38: 1-6 = hh_gender | P38: GeoPoll [5/6/2025]: Would suggest changing the order so this question comes directly after resp_id and updating the conditional logic so respondent is only asked if they are not the head of household. Kindly advise if ok? FAO=OK | Q38: For any response, go to [next question] | T38: =1 | W38: no | AA38: 7.0248413 | AB38: =IF(AA38="","",AA38*T38) | AC38: =IF(W38="yes",AB38,"")
A39: =A38+1 | B39: hh_gender | C39: hh_gender | D39: Is the head of your household male or female? [OPERATOR: SINGLE RESPONSE.] 1)Male 2)Female 3)DON'T KNOW 4)REFUSED | E39: =LEN(D39) | F39: Le chef de votre ménage est-il un homme ou une femme? [OPÉRATEUR/OPÉRATRICE: RÉPONSE UNIQUE.] 1)Homme 2)Femme 3)NE SAIT PAS 4)REFUSÉ | G39: =LEN(F39) | H39: Je, mkuu wa nyumba yako ni mwanamume au mwanamke?_x000D_ _x000D_ [OPERATOR: JIBU MOJA.]_x000D_ _x000D_ 1)Mwanaume_x000D_ 2)Mwanamke_x000D_ 3)SIJUE_x000D_ 4)KUKATALA | I39: =LEN(H39) | J39: Single Choice | K39: NA | L39: NA | M39: Form Type - Buttons | N39: NA | O39: 1-4 = hh_education | Q39: if hh_gender = 1-4, go to hh_education. | T39: =1 | W39: yes | AA39: 10.504534 | AB39: =IF(AA39="","",AA39*T39) | AC39: =IF(W39="yes",AB39,"")
A40: =A39+1 | B40: hh_education | C40: hh_education | D40: What is the educational level attained by the head of household? [OPERATOR: SINGLE RESPONSE.] 1)None or did not complete primary school 2)Completed primary school 3)Completed secondary school 4)Completed higher education [University / College] degree 5)Religious or informal education only 6)DON'T KNOW 7)REFUSED | E40: =LEN(D40) | F40: Quel est le niveau d'éducation du chef de votre ménage ? [OPÉRATEUR/OPÉRATRICE: RÉPONSE UNIQUE.] 1)Aucun ou n'a pas terminé l'école primaire 2)A terminé l'école primaire 3)A terminé l'école secondaire 4)Diplôme de l'enseignement supérieur [Université] 5)Enseignement religieux ou informel uniquement 6)NE SAIT PAS 7)REFUSÉ | G40: =LEN(F40) | H40: Je, mkuu wa nyumba ana kiwango gani cha elimu? [OPERATOR: JIBU MOJA.] 1)Hakuna au hakumaliza shule ya msingi 2)Kumaliza shule ya msingi 3)Kumaliza shule ya sekondari 4)Alimaliza elimu ya juu [Chuo kikuu/Chuo] 5)Elimu ya dini au isiyo rasmi pekee 6)SIJUE 7)KUKATALA | I40: =LEN(H40) | J40: Single Choice | K40: NA | L40: NA | M40: Form Type - Buttons | N40: NA | O40: 1-7 = hh_wealth_water | Q40: if hh_education = 1-7, go to hh_wealth. | T40: =1 | W40: yes | AA40: 12.421899 | AB40: =IF(AA40="","",AA40*T40) | AC40: =IF(W40="yes",AB40,"")
...

Sheet Crop list
C3: Select top 10 crops | D3: GeoPoll code | E3: Dataset code | F3: Label (EN) | G3: Label (FR)
C4: x | D4: {=_xlfn.SEQUENCE(90,1,1,1)} | E4: 1.1 | F4: Rice | G4: Riz
D5: 2 | E5: 1.2 | F5: Wheat | G5: Blé
C6: x | D6: 3 | E6: 1.3 | F6: Millet | G6: Mil
C7: x | D7: 4 | E7: 1.4 | F7: Sorghum | G7: Sorgho
C8: x | D8: 5 | E8: 1.5 | F8: Maize | G8: Maïs
D9: 6 | E9: 1.6 | F9: Barley | G9: Orge
D10: 7 | E10: 1.99 | F10: Other Cereal | G10: Autres céréales
C11: x | D11: 8 | E11: 2.1 | F11: Cassava | G11: Manioc
C12: x | D12: 9 | E12: 2.2 | F12: Potatoe | G12: Pommes de terre
D13: 10 | E13: 2.3 | F13: Sweet Potatoes | G13: Patates douces
D14: 11 | E14: 2.4 | F14: Yams | G14: Ignames
D15: 12 | E15: 2.5 | F15: Carrots | G15: Carottes
D16: 13 | E16: 2.6 | F16: Cocoyam | G16: Chou caraïbe
D17: 14 | E17: 2.99 | F17: Other tubers | G17: Autres tubercules
C18: x | D18: 15 | E18: 3.1 | F18: Beans | G18: Haricots
D19: 16 | E19: 3.2 | F19: Lentils | G19: Lentilles
D20: 17 | E20: 3.3 | F20: Peas | G20: Pois
C21: x | D21: 18 | E21: 3.4 | F21: Soybeans | G21: Soja
D22: 19 | E22: 3.5 | F22: Chickpeas | G22: Pois chiches
D23: 20 | E23: 3.6 | F23: Fava beans | G23: Fève
D24: 21 | E24: 3.7 | F24: Broad beans | G24: Fève large
D25: 22 | E25: 3.99 | F25: Other pulses | G25: Autres légumineuses
D26: 23 | E26: 4.1 | F26: Cabbage | G26: Choux
D27: 24 | E27: 4.2 | F27: Lettuce | G27: Laitue
D28: 25 | E28: 4.3 | F28: Spinach-Amaranth | G28: Epinards-Amaranthe
D29: 26 | E29: 4.4 | F29: Cassava leaves | G29: Feuilles de manioc
D30: 27 | E30: 4.5 | F30: Potatoe leaves | G30: Feuilles de pomme de terre
D31: 28 | E31: 4.6 | F31: Moringa | G31: Moringa
D32: 29 | E32: 4.7 | F32: Sorrel Hibiscus / Rosselle | G32: Oseille Hibiscus / Rosselle
D33: 30 | E33: 4.9 | F33: Green salad herbs [thyme, parsley, mint, rocca, other] | G33: Herbes aromatiques [thym, persil, menthe, rocca, autres]
... D53: 50 | E53: 7.1 | F53: Sweet Banana | G53: Banane douce
C54: x | D54: 51 | E54: 7.2 | F54: Plantains | G54: Banane plantain
C55: x | D55: 52 | E55: 7.3 | F55: Papaya | G55: Papaye
D56: 53 | E56: 7.4 | F56: Mango | G56: Mangue
D57: 54 | E57: 7.5 | F57: Guava | G57: Goyave
D58: 55 | E58: 7.6 | F58: Pineapple | G58: Ananas
D59: 56 | E59: 7.7 | F59: Avocado | G59: Avocat
D60: 57 | E60: 7.8 | F60: Water Melon | G60: Pastèques
D61: 58 | E61: 7.9 | F61: Dates | G61: Dattes
...

Sheet Additional information
C2: Original | D2: Replacement (EN) | E2: Replacement (FR) | F2: Comment (EN) | G2: Commentaire (FR) | H2: Examples (EN) | I2: Exemples (FR)
B3: FOR CORE QUESTIONS . (Mandatory to fill out) . | C3: ADMIN1 | E3: Province | F3: The first subdivision of the country, after national level; region; province; governorate; etc. | G3: La première subdivision du pays, après le niveau national ; par exemple, région ; province ; gouvernorat ; etc. | H3: region | I3: region
C4: ADMIN2 | E4: Territoire | F4: The second subdivision of the country; district; municipality; LGA; etc. | G4: La deuxième subdivision du pays ; par exemple, district, municipalité, LGA, etc. | H4: district | I4: district
C5: reference year | D5: last year | E5: l'année dernière | F5: Comparison questions will need need a reference year. Select whether you want to use "last year" or "a normal year" as a baseline. A "normal year" should refers to an average year from the past 5 years - make sure to train the enumerators accordingly. | G5: Les questions de comparaison auront besoin d'une année de référence. Choisissez si vous voulez utiliser "l'année dernière" ou "une année normale" comme année de référence. Une "année normale" doit correspondre à une année moyenne des 5 dernières années - veillez à former les recenseurs en conséquence. | H5: a normal year | I5: une année normale
C6: season | D6: Rainy season | E6: Saison des pluies | F6: Name the crop season(s) of interest if there are several cropping seasons in the country (e.g. Meher and Belg in Ethiopia, rainy season / flood-recession cropping / irrigated dry season in the Sahel). You can refer to the “last season” or “ongoing season". | G6: Nommez la ou les saisons culturales concernée(s) en ANGLAIS s'il y en a plusieurs dans le pays (par exemple, Meher et Belg en Ethiopie, saison des pluies / cultures de décrue / saison sèche irriguée au Sahel). Vous pouvez vous référer à la "dernière saison" ou "saison actuelle". | H6: wet season | I6: saison des pluies
C7: season phase | D7: =IF(E7="Pas encore en saison","Not yet in season",IF(E7="Préparation du terrain","Land preparation",IF(E7="Semis / plantation","Planting",IF(E7="Début de la croissance","Early growing",IF(E7="Croissance","Growing",IF(E7="Proche de la récolte","Maturing",IF(E7="Récolte","Harvesting",IF(E7="Post-récolte","Recently finished","")))))))) | E7: Proche de la récolte | F7: Indicate the phase of the season at the time of data collection. If the harvest from the season has not yet occurred, the question on crop harvest (crp_harv_change) will include the word “expected” (where #expected or nothing# is located). If the harvest has occured, "expected" will not be inserted in the question. | G7: Indiquez le stade de la saison culturale au moment de la collecte des données. Si la récolte de la saison n'a pas encore eu lieu, la question sur la récolte des cultures (crp_harv_change) inclura le mot "attendue" (là où se trouve #attendue ou rien#). Si la récolte a eu lieu, "attendue" ne sera pas inséré dans la question. | H7: Harvesting | I7: Récolte
C8: local measurement unit | F8: Specify the local measurement unit for land size, other than acres, hectares, square meters and square feet. If no other unit of measurement is needed, keep this cell blank. | G8: Indiquez l'unité utilisée localement pour mesurer la taille des terrains, autre que les acres, les hectares, les mètres carrés et les pieds carrés. Si aucune autre unité de mesure n'est nécessaire, garder cette cellule vide. | H8: Jeribs | I8: Jeribs
C9: local measurement unit conversion | D9: =IF(E9<>"",E9,"") | F9: Include the conversion of the local measurement unit to hectares. In other words, how many local measurement units are in 1 ha. | G9: Indiquez la conversion de l'unité de mesure locale en hectares. En d'autres termes, indiquez combien d'unités de mesure locales y a-t-il dans 1 ha. | H9: 0.2 | I9: 0.2
B10: FOR OPTIONAL QUESTIONS . (Fill out if applicable) . | C10: currency | E10: CDF | F10: The name of the main currency used nationally; USD; Naira; Rial; Pesos; etc. | G10: Nom de la principale devise utilisée au niveau national; par exemple, USD; Naira; Rial; Pesos; etc. | H10: Naira | I10: Naira
C11: MIN AMOUNT | E11: 0 | F11: The minimum amount for an income source should be set at 0 or any value below which it is not possible to do a transaction. For example, the smallest coin/banknote in a currency can be 1000, in which case you would set the minimum at 1000. Provide this input in the same currency as specified above. Only digits should be inputted. | G11: Le montant minimum d'une source de revenu doit être fixé à 0 ou à toute valeur en dessous de laquelle il n'est pas possible d'effectuer une transaction. Par exemple, la plus petite pièce/billet d'une devise peut être de 1000, auquel cas vous fixerez le minimum à 1000. Cette saisie doit être effectuée dans la même devise que celle spécifiée ci-dessus. Seuls des chiffres doivent être saisis. | H11: 5 | I11: 5
C12: MAX AMOUNT | E12: 10000000 | F12: Set the maximum amount for an income source over 3 months. Enumerators will not be able to input values above this amount in questions related to income amounts. Using previous representative surveys for this population, you can estimate this amount by using the mean income plus five (5) standard deviations, unless the country has high inflation. In the latter case, set the maximum value based on your country context (higher than the proposed approach). Provide this input in the same currency as specified above. Only digits should be inputted. | G12: Fixez le montant maximum pouvant être généré par une source de revenu sur 3 mois. Il ne sera pas possible pour les enquêteurs d'entrer des valeurs supérieures à ce montant dans les questions relatives aux montants des revenus. En vous basant sur des enquêtes précédentes représentatives de cette population, vous pouvez estimer ce montant en utilisant le revenu moyen plus cinq (5) écarts types, sauf si le pays connaît une forte inflation. Dans ce dernier cas, fixez la valeur maximale en fonction du contexte de votre pays (plus élevée que l'approche proposée). Cette saisie doit être effectuée dans la même devise que celle spécifiée ci-dessus. Seuls des chiffres doivent être saisis. | H12: 5000000 | I12: 5000000
C13: THRESHOLD | E13: 2000000 | F13: The threshold salary should be calculated to flag outliers (responses that look suspiciously high). Using previous representative surveys for this population, a good estimate is the average plus three (3) standard deviations, which should give the threshold for the 3 or 4% highest income values. Provide this input in the same currency as specified above. Only digits should be inputted. | G13: Le salaire seuil doit être calculé pour signaler les valeurs aberrantes (réponses qui semblent suspectes). En utilisant des enquêtes précédentes représentatives de cette population, une bonne estimation est la moyenne plus deux écarts types, ce qui devrait dégager le seuil pour les 3 ou 4% des valeurs de revenu les plus élevées. Cette saisie doit être effectuée dans la même devise que celle spécifiée ci-dessus. Seuls des chiffres doivent être saisis. | H13: 1200000 | I13: 1200000
C14: local vegetables | D14: Funbwa, spinach, cabbage, carrot | E14: Fumbwa, épinard, choux, carottes | F14: Input some common local vegetables [to be used as examples in the food consumption score indicator]. | G14: Saisissez quelques légumes locaux courants [à utiliser comme exemples dans l'indicateur de score de consommation alimentaire]. | H14: eggplants, zucchini, cauliflower | I14: aubergines, courgettes, choux-fleurs
C15: local fruits | D15: bananas, oranges, mangos | E15: bananes, oranges, mangues | F15: Input some common local fruits [to be used as examples in the food consumption score indicator]. | G15: Indiquez quelques fruits locaux courants [à utiliser comme exemples dans l'indicateur de score de consommation alimentaire]. | H15: apples, bananas, oranges | I15: pommes, bananes, oranges
B17: FILL OUT FOR QUESTIONNAIRE DURATION ESTIMATION . | C17: Expected percentage of respondents cultivating crops | D17: =IF(E17="","",E17) | E17: 0.75 | F17: If the survey is representative and has no quotas, write the proportion of rural households cultivating crops at country level, or if the survey follows a previous round with identical sample design, just report the percentage from the previous round. If you are using quotas, calculate the ratio of the quota over the minimum sample size at the level where the quota is implemented (so if you have a minimum sample size per strata of 110 with a quota of 100 crop producers, then it's 100/110 = 91% (the maximum you should write is 100%). | G17: Si l'enquête est représentative et ne comporte pas de quotas, écrivez la proportion de ménages ruraux impliqués dans les cultures au niveau du pays, ou si l'enquête suit un cycle précédent avec un plan d'échantillonnage identique, indiquez simplement le pourcentage du cycle précédent. Si vous utilisez des quotas, calculez le rapport entre le quota et la taille minimale de l'échantillon au niveau où le quota est appliqué (ainsi, si vous avez une taille minimale d'échantillon par strate de 110 avec un quota de 100 producteurs de cultures, alors c'est 100/110 = 91% (le maximum que vous devez écrire est 100%). | H17: 0.91 | I17: 0.91
C18: Expected percentage of respondents raising livestock | D18: =IF(E18="","",E18) | E18: 0.2 | F18: If the survey is representative and has no quotas, write the proportion of rural households raising livestock at country level, or if the survey follows a previous round with identical sample design, just report the percentage from the previous round. If you are using quotas, calculate the ratio of the quota over the minimum sample size at the level where the quota is implemented (so if you have a minimum sample size of 110 but a quota of 100 livestock producers, then it's 100/110 = 91% (the maximum you should write is 100%) | G18: Si l'enquête est représentative et ne comporte pas de quotas, écrivez la proportion de ménages ruraux impliqués dans l'élevage, ou si l'enquête suit un cycle précédent avec un plan d'échantillonnage identique, indiquez simplement le pourcentage du cycle précédent. Si vous utilisez des quotas, calculez le rapport entre le quota et la taille minimale de l'échantillon au niveau où le quota est appliqué (ainsi, si vous avez une taille minimale d'échantillon par strate de 110 avec un quota de 100 éleveurs, alors c'est 100/110 = 91% (le maximum que vous devez écrire est 100%). | H18: 0.91 | I18: 0.91
C19: Expected percentage of respondents involved in fishery | D19: =IF(E19="","",E19) | E19: 0.05 | F19: If the survey is representative and has no quotas, write the proportion of rural households involved in fisheries or aquaculture, otherwise if you are using quotas, calculate the ratio of the quota over the sample size at the level where the quota is implemented. (so if you haven't set a quota, and you expect to have a representative proportion of fishermen, just write the percentage of fishermen in the population you are targeting, in the example to the right, 5%) | G19: Si l'enquête est représentative et ne comporte pas de quotas, écrivez la proportion de ménages ruraux impliqués dans la pêche ou l'aquaculture; sinon, si vous utilisez des quotas, calculez le rapport entre le quota et la taille de l'échantillon au niveau où le quota est appliqué (ainsi, si vous n'avez pas fixé de quota, et que vous pensez avoir une proportion représentative de pêcheurs, écrivez simplement le pourcentage de pêcheurs dans la population que vous ciblez, dans l'exemple à droite, 5%). | H19: 0.05 | I19: 0.05
